#VRML_SIM R2023a utf8

PROTO AIBot [
  field SFString   name          "AIbot"
  field SFVec3f    translation   0 0 0
  field SFRotation rotation      0 0 1 0
  field SFString   controller    "AI"
  field SFString{"bumper", "force", "force-3d"} touchSensorType "bumper"
]
{   
  Robot {
    name IS name
    translation IS translation
    rotation IS rotation
    controller IS controller
    children [
        DEF head Hinge2Joint {
          jointParameters HingeJointParameters {
            position -0.2
            axis 0 1 0
            anchor 0.1 0 0
          }
          jointParameters2 JointParameters {
          }
          device [
            RotationalMotor {
              name "MotorHeadY"
              maxTorque 1000
            }
            PositionSensor {
              name "PSensorHeadY"
            }
          ]
          device2 [
            RotationalMotor {
              name "MotorHeadZ"
              maxTorque 1000
            }
            PositionSensor {
              name "PSensorHeadZ"
            }
          ]
          endPoint Solid {
            translation -0.00780824910359644 -2.378911947195937e-06 -0.021855044405697504
            rotation 0 -1 0 0.1999999999999989
            children [
              DEF left_eye Camera {
                translation -0.0586601 -0.0770091 0.0625
                rotation -0.10124704903090816 0.012681806141418225 -0.9947804817423411 2.6381
                children [
                  DEF left_eye Transform {
                    translation -0.02 0 -0.01
                    rotation 0 1 0 0
                    children [
                      Shape {
                        appearance PBRAppearance {
                          baseColor 0 0 0
                        }
                        geometry Sphere {
                          radius 0.026
                        }
                      }
                    ]
                  }
                ]
                name "left_camera"
                boundingObject USE left_eye
                fieldOfView 3
                width 74
                height 19
              }
              DEF right_eye Camera {
                translation -0.0586601 0.0770091 0.0625
                rotation 0.0944626446130286 0.03982601880912104 0.9947314697939985 2.60314
                children [
                  DEF right_eye Transform {
                    translation -0.02 0 -0.01
                    rotation 0 1 0 0
                    children [
                      Shape {
                        appearance PBRAppearance {
                          baseColor 0 0 0
                        }
                        geometry Sphere {
                          radius 0.026
                        }
                      }
                    ]
                  }
                ]
                name "right_camera"
                boundingObject USE right_eye
                fieldOfView 3
                width 74
                height 19
              }
              DEF abstract_eye Camera {
                translation 0 0 0.3
                rotation 0 1 0 -1.5707953071795862
                fieldOfView 3.1415
                width 38
                height 38
                projection "spherical"
              }
              DEF left_antenna Hinge2Joint {
                jointParameters HingeJointParameters {
                  position -0.1
                  axis 0 1 0
                  anchor -0.0845 -0.04 0.02
                }
                jointParameters2 JointParameters {
                  position 0.6
                }
                device [
                  RotationalMotor {
                    name "MotorAntennaeL1"
                  }
                  PositionSensor {
                    name "PSensorAntennaeL1"
                  }
                ]
                device2 [
                  RotationalMotor {
                    name "MotorAntennaeL2"
                  }
                  PositionSensor {
                    name "PSensorAntennaeL2"
                  }
                ]
                endPoint Solid {
                  translation -0.1793500292648481 -0.10521620567712639 0.01048325341641608
                  rotation -0.3105085477715542 0.9081150897021436 0.2809117755026805 1.5670171005306572
                  children [
                    HingeJoint {
                      jointParameters HingeJointParameters {
                        position 1
                        anchor 0 0 -0.12
                      }
                      device [
                        RotationalMotor {
                          name "MotorAntennaeL3"
                        }
                        PositionSensor {
                          name "PSensorAntennaeL3"
                        }
                      ]
                      endPoint Solid {
                        translation 0 0.13776983698767287 -0.20846099502826118
                        rotation 1 0 0 0.9999999999999998
                        children [
                          DEF OSensorL Transform {
                            translation 0 0 -0.16
                          }
                          Receiver {
                            translation 0 0 -0.16
                            name "OSensorL"
                            model "OSensorL"
                            channel 11
                          }
                          DistanceSensor {
                            translation 0 0 -0.15
                            name "DSensorL"
                            type "infra-red"
                          }
                          DEF antennae_s2 Shape {
                            appearance DEF antenna PBRAppearance {
                              baseColor 0 0 0
                              roughness 0.2
                              metalness 0.4
                            }
                            geometry Capsule {
                              height 0.317
                              radius 0.005
                            }
                          }
                        ]
                        boundingObject USE antennae_s2
                      }
                    }
                    DEF antennae_s1 Shape {
                      appearance USE antenna
                      geometry Capsule {
                        height 0.224
                        radius 0.0075
                      }
                    }
                  ]
                  boundingObject USE antennae_s1
                }
              }
              DEF right_antenna Hinge2Joint {
                jointParameters HingeJointParameters {
                  position -0.1
                  axis 0 1 0
                  anchor -0.083 0.04 0.02
                }
                jointParameters2 JointParameters {
                  position -0.6
                }
                device [
                  RotationalMotor {
                    name "MotorAntennaeR1"
                  }
                  PositionSensor {
                    name "PSensorAntennaeR1"
                  }
                ]
                device2 [
                  RotationalMotor {
                    name "MotorAntennaeR2"
                  }
                  PositionSensor {
                    name "PSensorAntennaeR2"
                  }
                ]
                endPoint Solid {
                  translation -0.17530427090362694 0.10346581400960186 0.010738681246798037
                  rotation 0.31050854777155407 0.9081150897021435 -0.28091177550268065 1.5670171005306586
                  children [
                    HingeJoint {
                      jointParameters HingeJointParameters {
                        position -1
                        anchor 0 0 -0.12
                      }
                      device [
                        RotationalMotor {
                          name "MotorAntennaeR3"
                        }
                        PositionSensor {
                          name "PSensorAntennaeR3"
                        }
                      ]
                      endPoint Solid {
                        translation 0 -0.13776983698767287 -0.20846099502826118
                        rotation -1 0 0 0.9999999999999998
                        children [
                          DEF OSensorR Transform {
                            translation 0 0 -0.16
                          }
                          Receiver {
                            translation 0 0 -0.16
                            name "OSensorR"
                            model "OSensorR"
                            channel 12
                          }
                          DistanceSensor {
                            translation 0 0 -0.15
                            name "DSensorR"
                            type "infra-red"
                          }
                          DEF antennae_s2 Shape {
                            appearance USE antenna
                            geometry Capsule {
                              height 0.317
                              radius 0.005
                            }
                          }
                        ]
                        boundingObject USE antennae_s2
                      }
                    }
                    DEF antennae_s1 Shape {
                      appearance USE antenna
                      geometry Capsule {
                        height 0.224
                        radius 0.0075
                      }
                    }
                  ]
                  name "solid(1)"
                  boundingObject USE antennae_s1
                }
              }
              DEF ShapeHead Transform {
                rotation 1 0 0 -1.5707953071795862
                children [
                  Shape {
                    appearance DEF AppHead PBRAppearance {
                      baseColor 0.3 0 0
                      roughness 0.5
                      metalness 0.1
                    }
                    geometry Capsule {
                      height 0.0088
                      radius 0.1
                    }
                  }
                ]
              }
            ]
            name "head"
            boundingObject USE ShapeHead
            physics Physics {
              density 600
              centerOfMass [
                0 0 0
              ]
            }
          }
        }
        DEF abdomen Hinge2Joint {
          jointParameters HingeJointParameters {
            position 0.5000942865281939
            axis 0 1 0
            anchor 0.4838 0 0
          }
          jointParameters2 JointParameters {
            position 4.054555359920099e-06
          }
          device [
            RotationalMotor {
              name "MotorAbdomenY"
              maxTorque 1000
            }
            PositionSensor {
              name "PSensorAbdomenY"
            }
          ]
          device2 [
            RotationalMotor {
              name "MotorAbdomenZ"
              maxTorque 1000
            }
            PositionSensor {
              name "PSensorAbdomenZ"
            }
          ]
          endPoint Solid {
            translation 0.5857663537386506 3.2215299623620707e-07 -0.05572154273735869
            rotation 3.428299148208603e-06 -0.9999999999921036 2.009823432083401e-06 1.070701020658289
            children [
              DEF ShapeAbdomen Transform {
                children [
                  Shape {
                    appearance DEF AppAbdomen PBRAppearance {
                      baseColor 0.05 0 0
                      roughness 0.2
                      metalness 0.2
                    }
                    geometry Capsule {
                      bottom FALSE
                      height 0.07445
                      radius 0.09343
                    }
                  }
                  Transform {
                    translation 0 0 -0.117
                    rotation 0 1 0 3.14159
                    children [
                      Shape {
                        appearance USE AppAbdomen
                        geometry Cone {
                          bottomRadius 0.0934
                          height 0.16
                        }
                      }
                    ]
                  }
                ]
              }
            ]
            name "abdomen"
            boundingObject Transform {
              translation 0 0 -0.03
              children [
                Shape {
                  geometry Capsule {
                    height 0.13
                    radius 0.0934
                    subdivision 16
                  }
                }
              ]
            }
            physics Physics {
              density 600
            }
          }
        }
        DEF legFL Hinge2Joint {
          jointParameters HingeJointParameters {
            position -0.012506501705307347
            axis 0 0 1
            anchor 0.23902 -0.07 -0.02
          }
          jointParameters2 JointParameters {
            position 2.461773500979066e-05
            axis 1 0 0
          }
          device [
            PositionSensor {
              name "PSensorLegLF1"
            }
            DEF motor1 RotationalMotor {
              name "MotorLegLF1"
              maxTorque 50
            }
          ]
          device2 [
            PositionSensor {
              name "PSensorLegLF2"
            }
            DEF motor2 RotationalMotor {
              name "MotorLegLF2"
              maxTorque 50
            }
          ]
          endPoint DEF solid Solid {
            translation 0.23999992299565712 -0.07001228505522739 -0.020000000659014132
            rotation -0.8589368554307588 0.3621011362799157 -0.3620914877313651 1.7222382896122623
            children [
              DEF coxa HingeJoint {
                jointParameters HingeJointParameters {
                  position -0.32805736002699504
                  anchor 0 0 -0.02
                }
                device [
                  DEF motor RotationalMotor {
                    name "MotorLegLF3"
                    maxTorque 50
                  }
                  PositionSensor {
                    name "PSensorLegLF3"
                  }
                ]
                endPoint DEF solid Solid {
                  translation 0 -0.03866455181200359 -0.13360040683541946
                  rotation -1 0 0 0.3280573600269953
                  children [
                    DEF femur HingeJoint {
                      jointParameters HingeJointParameters {
                        position 1.5693745994518729
                        anchor 0 0 -0.13
                      }
                      device [
                        DEF motor RotationalMotor {
                          name "MotorLegLF4"
                          maxTorque 50
                        }
                        PositionSensor {
                          name "PSensorLegLF4"
                        }
                      ]
                      endPoint DEF solid Solid {
                        translation 0 0.10399989489196729 -0.13014785959386294
                        rotation 0.9999999999999999 0 0 1.5693745994518729
                        children [
                          DEF tibia HingeJoint {
                            jointParameters HingeJointParameters {
                              position 1.5804940142299602e-05
                              anchor 0 0 -0.104
                            }
                            device [
                              DEF motor RotationalMotor {
                                name "MotorLegLF5"
                                maxTorque 50
                              }
                              PositionSensor {
                                name "PSensorLegLF5"
                              }
                            ]
                            endPoint Solid {
                              translation 0 2.6724940177983608e-06 -0.2099999999661328
                              rotation 1 0 0 2.55811928014723e-05
                              children [
                                Solid {
                                  translation 0 0 -0.11
                                  children [
                                    DEF TSensorLegLF TouchSensor {
                                      name "TSensorLegLF"
                                      boundingObject Sphere {
                                        radius 0.01
                                      }
                                      physics Physics {
                                        density 20
                                        centerOfMass [
                                          0 0 0
                                        ]
                                      }
                                    }
                                    DEF ShapeClaw Shape {
                                      appearance DEF AppLeg PBRAppearance {
                                        baseColor 0 0 0
                                        roughness 0.5
                                        metalness 0.4
                                      }
                                      geometry Sphere {
                                        radius 0.0095
                                      }
                                    }
                                  ]
                                  name "fl_tarsus_claw"
                                  boundingObject USE ShapeClaw
                                  physics Physics {
                                  }
                                }
                                DEF ShapeFTarsus Shape {
                                  appearance DEF AppLeg PBRAppearance {
                                    baseColor 0 0 0
                                    roughness 0.5
                                    metalness 0.4
                                  }
                                  geometry Capsule {
                                    height 0.19333
                                    radius 0.00584
                                  }
                                }
                              ]
                              name "fl_tarsus"
                              boundingObject USE ShapeFTarsus
                              physics Physics {
                              }
                            }
                          }
                          DEF ShapeFTibia Shape {
                            appearance DEF AppLeg PBRAppearance {
                              baseColor 0 0 0
                              roughness 0.5
                              metalness 0.4
                            }
                            geometry Capsule {
                              height 0.19346
                              radius 0.01095
                            }
                          }
                        ]
                        name "fl_tibia"
                        boundingObject USE ShapeFTibia
                        physics Physics {
                        }
                      }
                    }
                    DEF ShapeFFemur Shape {
                      appearance DEF AppLeg PBRAppearance {
                        baseColor 0 0 0
                        roughness 0.5
                        metalness 0.4
                      }
                      geometry Capsule {
                        height 0.2175
                        radius 0.0146
                      }
                    }
                  ]
                  name "fl_femur"
                  boundingObject USE ShapeFFemur
                  physics Physics {
                  }
                }
              }
              DEF ShapeFCoxa Shape {
                appearance DEF AppLeg PBRAppearance {
                  baseColor 0 0 0
                  roughness 0.5
                  metalness 0.4
                }
                geometry Capsule {
                  height 0.009
                  radius 0.01095
                }
              }
            ]
            name "fl_coxa"
            boundingObject USE ShapeFCoxa
            physics Physics {
            }
          }
        }
        DEF legFR Hinge2Joint {
          jointParameters HingeJointParameters {
            position 0.01248690505659255
            axis 0 0 1
            anchor 0.23902 0.07 -0.02
          }
          jointParameters2 JointParameters {
            position 1.2616692036325559e-05
            axis 1 0 0
          }
          device [
            DEF motor1 RotationalMotor {
              name "MotorLegRF1"
              maxTorque 50
            }
            PositionSensor {
              name "PSensorLegRF1"
            }
          ]
          device2 [
            PositionSensor {
              name "PSensorLegRF2"
            }
            DEF motor2 RotationalMotor {
              name "MotorLegRF2"
              maxTorque 50
            }
          ]
          endPoint DEF solid Solid {
            translation 0.23999992353407487 0.07001224203276478 -0.020000000000083198
            rotation -0.2856572547184908 0.6776473775034736 -0.6776385205914434 2.5850887552485466
            children [
              DEF coxa HingeJoint {
                jointParameters HingeJointParameters {
                  position -0.4262373769787078
                  anchor 0 0 -0.02
                }
                device [
                  DEF motor RotationalMotor {
                    name "MotorLegRF3"
                    maxTorque 50
                  }
                  PositionSensor {
                    name "PSensorLegRF3"
                  }
                ]
                endPoint DEF solid Solid {
                  translation 2.2204460492499443e-16 -0.049613731698960016 -0.12926334072732237
                  rotation -1 0 0 0.4262373769787082
                  children [
                    DEF femur HingeJoint {
                      jointParameters HingeJointParameters {
                        position 1.6659679224776875
                        anchor 0 0 -0.13
                      }
                      device [
                        DEF motor RotationalMotor {
                          name "MotorLegRF4"
                          maxTorque 50
                        }
                        PositionSensor {
                          name "PSensorLegRF4"
                        }
                      ]
                      endPoint DEF solid Solid {
                        translation -4.237176950638828e-06 0.10351655786007992 -0.12011777361815776
                        rotation 0.9999999999993237 7.687297369421002e-07 8.728262855686264e-07 1.6659683464236397
                        children [
                          DEF tibia HingeJoint {
                            jointParameters HingeJointParameters {
                              position -6.243220587455381e-07
                              anchor 0 0 -0.104
                            }
                            device [
                              DEF motor RotationalMotor {
                                name "MotorLegRF5"
                                maxTorque 50
                              }
                              PositionSensor {
                                name "PSensorLegRF5"
                              }
                            ]
                            endPoint Solid {
                              translation 0 -6.82349326421615e-08 -0.20999999999997623
                              rotation -1 0 0 6.244279992508009e-07
                              children [
                                Solid {
                                  translation 0 0 -0.106
                                  children [
                                    DEF TSensorLegRF TouchSensor {
                                      name "TSensorLegRF"
                                      boundingObject Sphere {
                                        radius 0.01
                                      }
                                      physics Physics {
                                        density 20
                                        centerOfMass [
                                          0 0 0
                                        ]
                                      }
                                    }
                                    DEF ShapeClaw Shape {
                                      appearance USE AppLeg
                                      geometry Sphere {
                                        radius 0.0095
                                      }
                                    }
                                  ]
                                  name "fl_tarsus_claw"
                                  boundingObject USE ShapeClaw
                                  physics Physics {
                                  }
                                }
                                DEF ShapeFTarsus Shape {
                                  appearance DEF AppLeg PBRAppearance {
                                    baseColor 0 0 0
                                    roughness 0.5
                                    metalness 0.4
                                  }
                                  geometry Capsule {
                                    height 0.19333
                                    radius 0.00584
                                  }
                                }
                                TouchSensor {
                                  translation 0 0 -0.106
                                  name "TSensorLegFR"
                                  boundingObject USE ShapeClaw
                                }
                              ]
                              name "fl_tarsus"
                              boundingObject USE ShapeFTarsus
                              physics Physics {
                              }
                            }
                          }
                          DEF ShapeFTibia Shape {
                            appearance USE AppLeg
                            geometry Capsule {
                              height 0.19346
                              radius 0.01095
                            }
                          }
                        ]
                        name "fl_tibia"
                        boundingObject USE ShapeFTibia
                        physics Physics {
                        }
                      }
                    }
                    DEF ShapeFFemur Shape {
                      appearance USE AppLeg
                      geometry Capsule {
                        height 0.2175
                        radius 0.0146
                      }
                    }
                  ]
                  name "fl_femur"
                  boundingObject USE ShapeFFemur
                  physics Physics {
                  }
                }
              }
              DEF ShapeFCoxa Shape {
                appearance USE AppLeg
                geometry Capsule {
                  height 0.009
                  radius 0.01095
                }
              }
            ]
            name "fr_coxa"
            boundingObject USE ShapeFCoxa
            physics Physics {
            }
          }
        }
        DEF legML Hinge2Joint {
          jointParameters HingeJointParameters {
            position 0.012513736693773862
            axis 0 0 1
            anchor 0.34 -0.02 -0.02
          }
          jointParameters2 JointParameters {
            position -0.0006077773603365647
            axis 1 0 0
          }
          device [
            DEF motor1 RotationalMotor {
              name "MotorLegLM1"
              maxTorque 50
            }
            PositionSensor {
              name "PSensorLegLM1"
            }
          ]
          device2 [
            DEF motor2 RotationalMotor {
              name "MotorLegLM2"
              maxTorque 50
            }
            PositionSensor {
              name "PSensorLegLM2"
            }
          ]
          endPoint DEF solid Solid {
            translation 0.3505974670275055 -0.04987404397316367 -0.029982162141062356
            rotation -0.9999608766122718 -0.006256745863813235 0.0062528694223168615 1.571442208176398
            children [
              DEF ShapeMCoxa Shape {
                appearance USE AppLeg
                geometry Capsule {
                  height 0.0146
                  radius 0.0219
                }
              }
              DEF coxa HingeJoint {
                jointParameters HingeJointParameters {
                  position -0.49123676850189874
                  anchor 0 0 -0.027
                }
                device [
                  DEF motor RotationalMotor {
                    name "MotorLegLM3"
                    maxTorque 50
                  }
                  PositionSensor {
                    name "PSensorLegLM3"
                  }
                ]
                endPoint DEF solid Solid {
                  translation 0 -0.0680121420946511 -0.15833434853153425
                  rotation -1 0 0 0.4912367685018989
                  children [
                    DEF ShapeMFemur Shape {
                      appearance USE AppLeg
                      geometry Capsule {
                        height 0.26
                        radius 0.0146
                      }
                    }
                    DEF femur HingeJoint {
                      jointParameters HingeJointParameters {
                        position 1.4938522903334353
                        anchor 0 0 -0.147
                      }
                      device [
                        DEF motor RotationalMotor {
                          name "MotorLegLM4"
                          maxTorque 50
                        }
                        PositionSensor {
                          name "PSensorLegLM4"
                        }
                      ]
                      endPoint DEF solid Solid {
                        translation 0 0.12263607593876238 -0.15645478071360927
                        rotation 1 0 0 1.493852290333435
                        children [
                          DEF ShapeMTibia Shape {
                            appearance USE AppLeg
                            geometry Capsule {
                              height 0.22074
                              radius 0.01095
                            }
                          }
                          DEF tibia HingeJoint {
                            jointParameters HingeJointParameters {
                              position -6.570147891412914e-07
                              anchor 0 0 -0.121
                            }
                            device [
                              DEF motor RotationalMotor {
                                name "MotorLegLM5"
                                maxTorque 50
                              }
                              PositionSensor {
                                name "PSensorLegLM5"
                              }
                            ]
                            endPoint Solid {
                              translation 0 4.5570753151031786e-07 -0.25299999999922157
                              rotation 1 0 0 3.4148051880372e-06
                              children [
                                DEF ShapeMTarsus Shape {
                                  appearance USE AppLeg
                                  geometry Capsule {
                                    height 0.254
                                    radius 0.0059
                                  }
                                }
                                Solid {
                                  translation 0 0 -0.14
                                  children [
                                    DEF TSensorLegLM TouchSensor {
                                      name "TSensorLegLM"
                                      boundingObject Sphere {
                                        radius 0.01
                                      }
                                      physics Physics {
                                        density 20
                                        centerOfMass [
                                          0 0 0
                                        ]
                                      }
                                    }
                                    DEF ShapeClaw Shape {
                                      appearance USE AppLeg
                                      geometry Sphere {
                                        radius 0.0095
                                      }
                                    }
                                  ]
                                  name "fl_tarsus_claw"
                                  boundingObject USE ShapeClaw
                                  physics Physics {
                                  }
                                }
                                DEF t_sensor TouchSensor {
                                  translation 0 0 -0.14
                                  name "TSensorLegML"
                                  boundingObject USE ShapeClaw
                                }
                              ]
                              boundingObject USE ShapeMTarsus
                              physics Physics {
                              }
                            }
                          }
                        ]
                        boundingObject USE ShapeMTibia
                        physics Physics {
                        }
                      }
                    }
                  ]
                  boundingObject USE ShapeMFemur
                  physics Physics {
                  }
                }
              }
            ]
            boundingObject USE ShapeMCoxa
            physics Physics {
            }
          }
        }
        DEF legMR Hinge2Joint {
          jointParameters HingeJointParameters {
            position -0.014527110593678744
            axis 0 0 1
            anchor 0.34 0.02 -0.02
          }
          jointParameters2 JointParameters {
            position 9.950707675717525e-05
            axis 1 0 0
          }
          device [
            DEF motor1 RotationalMotor {
              name "MotorLegRM1"
              maxTorque 50
            }
            PositionSensor {
              name "PSensorLegRM1"
            }
          ]
          device2 [
            DEF motor2 RotationalMotor {
              name "MotorLegRM2"
              maxTorque 50
            }
            PositionSensor {
              name "PSensorLegRM2"
            }
          ]
          endPoint DEF solid Solid {
            translation 0.35043475302890026 0.04985227099510724 -0.02999789206086835
            rotation 0.005136126902922662 0.7071331312378105 -0.7070617758769361 3.1518621760348307
            children [
              DEF ShapeMCoxa Shape {
                appearance USE AppLeg
                geometry Capsule {
                  height 0.0146
                  radius 0.0219
                }
              }
              DEF coxa HingeJoint {
                jointParameters HingeJointParameters {
                  position -0.39306194219930674
                  anchor 0 0 -0.027
                }
                device [
                  DEF motor RotationalMotor {
                    name "MotorLegRM3"
                    maxTorque 50
                  }
                  PositionSensor {
                    name "PSensorLegRM3"
                  }
                ]
                endPoint DEF solid Solid {
                  translation 0 -0.05857160238793804 -0.1643397969165831
                  rotation -1 0 0 0.3930619421993069
                  children [
                    DEF ShapeMFemur Shape {
                      appearance USE AppLeg
                      geometry Capsule {
                        height 0.26
                        radius 0.0146
                      }
                    }
                    DEF femur HingeJoint {
                      jointParameters HingeJointParameters {
                        position 1.407836706894386
                        anchor 0 0 -0.147
                      }
                      device [
                        DEF motor RotationalMotor {
                          name "MotorLegRM4"
                          maxTorque 50
                        }
                        PositionSensor {
                          name "PSensorLegRM4"
                        }
                      ]
                      endPoint DEF solid Solid {
                        translation 0 0.12137042698712844 -0.16695543667680549
                        rotation 1 0 0 1.4078367068943862
                        children [
                          DEF ShapeMTibia Shape {
                            appearance USE AppLeg
                            geometry Capsule {
                              height 0.22074
                              radius 0.01095
                            }
                          }
                          DEF tibia HingeJoint {
                            jointParameters HingeJointParameters {
                              position 1.9066322264483884e-05
                              anchor 0 0 -0.121
                            }
                            device [
                              DEF motor RotationalMotor {
                                name "MotorLegRM5"
                                maxTorque 50
                              }
                              PositionSensor {
                                name "PSensorLegRM5"
                              }
                            ]
                            endPoint Solid {
                              translation 0 2.5167545387560585e-06 -0.25299999997600875
                              rotation 1 0 0 1.9066313795767047e-05
                              children [
                                DEF ShapeMTarsus Shape {
                                  appearance USE AppLeg
                                  geometry Capsule {
                                    height 0.254
                                    radius 0.0059
                                  }
                                }
                                Solid {
                                  translation 0 0 -0.14
                                  children [
                                    DEF TSensorLegRM TouchSensor {
                                      name "TSensorLegRM"
                                      boundingObject Sphere {
                                        radius 0.01
                                      }
                                      physics Physics {
                                        density 20
                                        centerOfMass [
                                          0 0 0
                                        ]
                                      }
                                    }
                                    DEF ShapeClaw Shape {
                                      appearance USE AppLeg
                                      geometry Sphere {
                                        radius 0.0095
                                      }
                                    }
                                  ]
                                  name "fl_tarsus_claw"
                                  boundingObject USE ShapeClaw
                                  physics Physics {
                                  }
                                }
                                TouchSensor {
                                  name "TSensorLegMR"
                                }
                              ]
                              boundingObject USE ShapeMTarsus
                              physics Physics {
                              }
                            }
                          }
                        ]
                        boundingObject USE ShapeMTibia
                        physics Physics {
                        }
                      }
                    }
                  ]
                  boundingObject USE ShapeMFemur
                  physics Physics {
                  }
                }
              }
            ]
            name "solid(1)"
            boundingObject USE ShapeMCoxa
            physics Physics {
            }
          }
        }
        DEF legHL Hinge2Joint {
          jointParameters HingeJointParameters {
            position -0.012437959289716093
            axis 0 0 1
            anchor 0.426276 -0.03 -0.0340389
          }
          jointParameters2 JointParameters {
            position -8.80658009445903e-06
            axis 1 0 0
          }
          device [
            DEF motor1 RotationalMotor {
              name "MotorLegLH1"
              maxTorque 50
            }
            PositionSensor {
              name "PSensorLegLH1"
            }
          ]
          device2 [
            DEF motor2 RotationalMotor {
              name "MotorLegLH2"
              maxTorque 50
            }
            PositionSensor {
              name "PSensorLegLH2"
            }
          ]
          endPoint DEF solid Solid {
            translation 0.42950220618281354 -0.07004324147300722 -0.030000175546557258
            rotation -0.86671668473683 -0.352705146330649 0.3527056395220719 1.7133653121195775
            children [
              DEF ShapeHCoxa Shape {
                appearance USE AppLeg
                geometry Capsule {
                  height 0.04926
                  radius 0.0219
                }
              }
              DEF coxa HingeJoint {
                jointParameters HingeJointParameters {
                  position -0.7866287070542753
                  anchor 0 0 -0.046
                }
                device [
                  DEF motor RotationalMotor {
                    name "MotorLegLH3"
                    maxTorque 50
                  }
                  PositionSensor {
                    name "PSensorLegLH3"
                  }
                ]
                endPoint DEF solid Solid {
                  translation 0 -0.1302676523315828 -0.1759474461311395
                  rotation -1 0 0 0.7866287070542752
                  children [
                    DEF ShapeHFemur Shape {
                      appearance USE AppLeg
                      geometry Capsule {
                        height 0.336
                        radius 0.0146
                      }
                    }
                    DEF femur HingeJoint {
                      jointParameters HingeJointParameters {
                        position 1.8155847163465133
                        anchor 0 0 -0.184
                      }
                      device [
                        DEF motor RotationalMotor {
                          name "MotorLegLH4"
                          maxTorque 50
                        }
                        PositionSensor {
                          name "PSensorLegLH4"
                        }
                      ]
                      endPoint DEF solid Solid {
                        translation 0 0.15717055817404976 -0.14473913343726053
                        rotation 1 0 0 1.8155847163465135
                        children [
                          DEF ShapeHTibia Shape {
                            appearance USE AppLeg
                            geometry Capsule {
                              height 0.3
                              radius 0.01095
                            }
                          }
                          DEF tibia HingeJoint {
                            jointParameters HingeJointParameters {
                              position -5.097534576906296e-06
                              anchor 0 0 -0.161
                            }
                            device [
                              DEF motor RotationalMotor {
                                name "MotorLegLH5"
                                maxTorque 50
                              }
                              PositionSensor {
                                name "PSensorLegLH5"
                              }
                            ]
                            endPoint Solid {
                              translation 0 -2.2045847576852218e-07 -0.33599999999985974
                              rotation -1 0 0 5.09750408011224e-06
                              children [
                                DEF ShapeHTarsus Shape {
                                  appearance USE AppLeg
                                  geometry Capsule {
                                    height 0.339
                                    radius 0.0059
                                  }
                                }
                                Solid {
                                  translation 0 0 -0.18
                                  children [
                                    DEF TSensorLegLH TouchSensor {
                                      name "TSensorLegLH"
                                      boundingObject Sphere {
                                        radius 0.01
                                      }
                                      physics Physics {
                                        density 20
                                        centerOfMass [
                                          0 0 0
                                        ]
                                      }
                                    }
                                    DEF ShapeClaw Shape {
                                      appearance USE AppLeg
                                      geometry Sphere {
                                        radius 0.0095
                                      }
                                    }
                                  ]
                                  name "fl_tarsus_claw"
                                  boundingObject USE ShapeClaw
                                  physics Physics {
                                  }
                                }
                                DEF t_sensor TouchSensor {
                                  translation 0 0 -0.18
                                  name "TSensorLegHL"
                                  boundingObject USE ShapeClaw
                                }
                              ]
                              boundingObject USE ShapeHTarsus
                              physics Physics {
                              }
                            }
                          }
                        ]
                        boundingObject USE ShapeHTibia
                        physics Physics {
                        }
                      }
                    }
                  ]
                  boundingObject USE ShapeHFemur
                  physics Physics {
                  }
                }
              }
            ]
            name "solid(2)"
            boundingObject USE ShapeHCoxa
            physics Physics {
            }
          }
        }
        DEF legHR Hinge2Joint {
          jointParameters HingeJointParameters {
            position 0.012486970080298594
            axis 0 0 1
            anchor 0.426276 0.03 -0.0340389
          }
          jointParameters2 JointParameters {
            position 6.834047066786066e-06
            axis 1 0 0
          }
          device [
            DEF motor1 RotationalMotor {
              name "MotorLegRH1"
              maxTorque 50
            }
            PositionSensor {
              name "PSensorLegRH1"
            }
          ]
          device2 [
            DEF motor2 RotationalMotor {
              name "MotorLegRH2"
              maxTorque 50
            }
            PositionSensor {
              name "PSensorLegRH2"
            }
          ]
          endPoint DEF solid Solid {
            translation 0.42950024258725633 0.07004348288728711 -0.030001001139923576
            rotation -0.2765138343984026 -0.6795396477036806 0.679533639038606 2.6020465131909827
            children [
              DEF ShapeHCoxa Shape {
                appearance USE AppLeg
                geometry Capsule {
                  height 0.04926
                  radius 0.0219
                }
              }
              DEF coxa HingeJoint {
                jointParameters HingeJointParameters {
                  position -0.8842349942499061
                  anchor 0 0 -0.046
                }
                device [
                  DEF motor RotationalMotor {
                    name "MotorLegRH3"
                    maxTorque 50
                  }
                  PositionSensor {
                    name "PSensorLegRH3"
                  }
                ]
                endPoint DEF solid Solid {
                  translation -6.333731270569002e-07 -0.1423199055789684 -0.16263177261431094
                  rotation -0.9999999999998295 5.58511244899269e-07 1.7002484146670281e-07 0.8842349942525355
                  children [
                    DEF ShapeHFemur Shape {
                      appearance USE AppLeg
                      geometry Capsule {
                        height 0.336
                        radius 0.0146
                      }
                    }
                    DEF femur HingeJoint {
                      jointParameters HingeJointParameters {
                        position 1.912967380977436
                        anchor 0 0 -0.184
                      }
                      device [
                        DEF motor RotationalMotor {
                          name "MotorLegRH4"
                          maxTorque 50
                        }
                        PositionSensor {
                          name "PSensorLegRH4"
                        }
                      ]
                      endPoint DEF solid Solid {
                        translation 0 0.15260860496759904 -0.12964364167970796
                        rotation 1 0 0 1.912967380977436
                        children [
                          DEF ShapeHTibia Shape {
                            appearance USE AppLeg
                            geometry Capsule {
                              height 0.3
                              radius 0.01095
                            }
                          }
                          DEF tibia HingeJoint {
                            jointParameters HingeJointParameters {
                              position 2.584346349128346e-07
                              anchor 0 0 -0.161
                            }
                            device [
                              DEF motor RotationalMotor {
                                name "MotorLegRH5"
                                maxTorque 50
                              }
                              PositionSensor {
                                name "PSensorLegRH5"
                              }
                            ]
                            endPoint Solid {
                              translation 0 2.6882423007687755e-08 -0.33600000000744046
                              rotation 1 0 0 2.5809568279517867e-07
                              children [
                                DEF ShapeHTarsus Shape {
                                  appearance USE AppLeg
                                  geometry Capsule {
                                    height 0.339
                                    radius 0.0059
                                  }
                                }
                                Solid {
                                  translation 0 0 -0.18
                                  children [
                                    DEF TSensorLegRH TouchSensor {
                                      name "TSensorLegRH"
                                      boundingObject Sphere {
                                        radius 0.01
                                      }
                                      physics Physics {
                                        density 20
                                        centerOfMass [
                                          0 0 0
                                        ]
                                      }
                                    }
                                    DEF ShapeClaw Shape {
                                      appearance USE AppLeg
                                      geometry Sphere {
                                        radius 0.0095
                                      }
                                    }
                                  ]
                                  name "fl_tarsus_claw"
                                  boundingObject USE ShapeClaw
                                  physics Physics {
                                  }
                                }
                                DEF t_sensor TouchSensor {
                                  translation 0 0 -0.18
                                  name "TSensorLegHR"
                                  boundingObject USE ShapeClaw
                                }
                              ]
                              boundingObject USE ShapeHTarsus
                              physics Physics {
                              }
                            }
                          }
                        ]
                        boundingObject USE ShapeHTibia
                        physics Physics {
                        }
                      }
                    }
                  ]
                  boundingObject USE ShapeHFemur
                  physics Physics {
                  }
                }
              }
            ]
            name "solid(3)"
            boundingObject USE ShapeHCoxa
            physics Physics {
            }
          }
        }
        DEF thorax Transform {
          translation 0.19 0 0
          rotation 0 1 0 -1.5707953071795862
          children [
            DEF ShapeThorax Shape {
              appearance USE AppLeg
              geometry Capsule {
                height 0.05839
                radius 0.06642
              }
            }
          ]
        }
        DEF petiole Transform {
          translation 0.368 0 0
          rotation 0 1 0 1.5708
          children [
            DEF ShapePetiole Shape {
              appearance USE AppLeg
              geometry Capsule {
                height 0.084
                radius 0.04
              }
            }
          ]
        }
        Pen {
          translation 0 0 -0.19
          inkColor 0.9411764740943909 0.6078431606292725 0.0941176488995552
          inkDensity 1
        }
    ]
  }
}