#VRML_SIM R2023a utf8

EXTERNPROTO "https://raw.githubusercontent.com/cyberbotics/webots/R2023a/projects/objects/backgrounds/protos/TexturedBackground.proto"
EXTERNPROTO "https://raw.githubusercontent.com/cyberbotics/webots/R2023a/projects/objects/backgrounds/protos/TexturedBackgroundLight.proto"
EXTERNPROTO "https://raw.githubusercontent.com/cyberbotics/webots/R2023a/projects/objects/floors/protos/UnevenTerrain.proto"

WorldInfo {
  basicTimeStep 8
}
Viewpoint {
  orientation 0.2337873321454828 -0.2719334153203702 -0.9334857797312698 4.7945999073276715
  position -1.8800635390896343 -17.51494645261624 10.793669034639684
}
TexturedBackground {
}
TexturedBackgroundLight {
  castShadows FALSE
}
UnevenTerrain {
  size 10 10 2
}
DEF ant Robot {
  translation 2.2862288880633055 -0.7938661999537189 1.6797139842200581
  rotation 0.35962101372958954 -0.4320144556370668 0.8270648321653575 0.23699493900477175
  children [
    DEF head Hinge2Joint {
      jointParameters HingeJointParameters {
        position -0.20000817840825094
        axis 0 1 0
        anchor 0.1 0 0
      }
      jointParameters2 JointParameters {
        position 6.807543524701702e-07
      }
      device [
        RotationalMotor {
          name "MotorHeadY"
          maxTorque 1000
        }
        PositionSensor {
          name "PSensorHeadY"
        }
      ]
      device2 [
        RotationalMotor {
          name "MotorHeadZ"
          maxTorque 1000
        }
        PositionSensor {
          name "PSensorHeadZ"
        }
      ]
      endPoint Solid {
        translation -0.007808070358903879 -2.4537957352537393e-06 -0.021855926104513982
        rotation -3.4037717623312004e-07 -0.9999999999941882 3.3922786389379627e-06 0.20000817840940602
        children [
          DEF left_eye Camera {
            translation -0.0586601 -0.0770091 0.0625
            rotation -0.10124704903090816 0.012681806141418225 -0.9947804817423411 2.6381
            children [
              DEF left_eye Transform {
                translation -0.02 0 -0.01
                rotation 0 1 0 0
                children [
                  Shape {
                    appearance PBRAppearance {
                      baseColor 0 0 0
                    }
                    geometry Sphere {
                      radius 0.026
                    }
                  }
                ]
              }
            ]
            name "left_camera"
            boundingObject USE left_eye
            fieldOfView 3
            width 74
            height 19
          }
          DEF right_eye Camera {
            translation -0.0586601 0.0770091 0.0625
            rotation 0.0944626446130286 0.03982601880912104 0.9947314697939985 2.60314
            children [
              DEF right_eye Transform {
                translation -0.02 0 -0.01
                rotation 0 1 0 0
                children [
                  Shape {
                    appearance PBRAppearance {
                      baseColor 0 0 0
                    }
                    geometry Sphere {
                      radius 0.026
                    }
                  }
                ]
              }
            ]
            name "right_camera"
            boundingObject USE right_eye
            fieldOfView 3
            width 74
            height 19
          }
          DEF abstract_eye Camera {
            translation 0 0 0.3
            rotation 0 1 0 -1.5707953071795862
            fieldOfView 3.1415
            width 38
            height 38
            projection "spherical"
          }
          DEF left_antenna Hinge2Joint {
            jointParameters HingeJointParameters {
              position 0.4
              axis 0 1 0
              anchor -0.0845 -0.04 0.02
            }
            jointParameters2 JointParameters {
              position 0.8956685134750993
            }
            device [
              RotationalMotor {
                name "MotorAntennaeL1"
              }
              PositionSensor {
                name "PSensorAntennaeL1"
              }
            ]
            device2 [
              RotationalMotor {
                name "MotorAntennaeL2"
              }
              PositionSensor {
                name "PSensorAntennaeL2"
              }
            ]
            endPoint Solid {
              translation -0.15098878160907753 -0.13016242711112203 0.048111005986480576
              rotation -0.27590847824049664 0.8663990909793129 0.4162056304102978 2.0989113103019195
              children [
                HingeJoint {
                  jointParameters HingeJointParameters {
                    position 1
                    anchor 0 0 -0.12
                  }
                  device [
                    RotationalMotor {
                      name "MotorAntennaeL3"
                    }
                    PositionSensor {
                      name "PSensorAntennaeL3"
                    }
                  ]
                  endPoint Solid {
                    translation 0 0.13776983698767287 -0.20846099502826118
                    rotation 1 0 0 0.9999999999999998
                    children [
                      DEF OSensorL Transform {
                        translation 0 0 -0.16
                      }
                      Receiver {
                        translation 0 0 -0.16
                        name "OSensorL"
                        model "OSensorL"
                        channel 11
                      }
                      DistanceSensor {
                        translation 0 0 -0.15
                        name "DSensorL"
                        type "infra-red"
                      }
                      DEF antennae_s2 Shape {
                        appearance DEF antenna PBRAppearance {
                          baseColor 0 0 0
                          roughness 0.2
                          metalness 0.4
                        }
                        geometry Capsule {
                          height 0.317
                          radius 0.005
                        }
                      }
                    ]
                    boundingObject USE antennae_s2
                  }
                }
                DEF antennae_s1 Shape {
                  appearance USE antenna
                  geometry Capsule {
                    height 0.224
                    radius 0.0075
                  }
                }
              ]
              boundingObject USE antennae_s1
            }
          }
          DEF right_antenna Hinge2Joint {
            jointParameters HingeJointParameters {
              position 0.3
              axis 0 1 0
              anchor -0.083 0.04 0.02
            }
            jointParameters2 JointParameters {
              position -0.704575528517515
            }
            device [
              RotationalMotor {
                name "MotorAntennaeR1"
              }
              PositionSensor {
                name "PSensorAntennaeR1"
              }
            ]
            device2 [
              RotationalMotor {
                name "MotorAntennaeR2"
              }
              PositionSensor {
                name "PSensorAntennaeR2"
              }
            ]
            endPoint Solid {
              translation -0.16481124218835239 0.11280265893895922 0.04530718283444956
              rotation 0.2465856371005638 0.9096034940552417 -0.3343905010286701 1.9599401100906158
              children [
                HingeJoint {
                  jointParameters HingeJointParameters {
                    position -1
                    anchor 0 0 -0.12
                  }
                  device [
                    RotationalMotor {
                      name "MotorAntennaeR3"
                    }
                    PositionSensor {
                      name "PSensorAntennaeR3"
                    }
                  ]
                  endPoint Solid {
                    translation 0 -0.13776983698767287 -0.20846099502826118
                    rotation -1 0 0 0.9999999999999998
                    children [
                      DEF OSensorR Transform {
                        translation 0 0 -0.16
                      }
                      Receiver {
                        translation 0 0 -0.16
                        name "OSensorR"
                        model "OSensorR"
                        channel 12
                      }
                      DistanceSensor {
                        translation 0 0 -0.15
                        name "DSensorR"
                        type "infra-red"
                      }
                      DEF antennae_s2 Shape {
                        appearance USE antenna
                        geometry Capsule {
                          height 0.317
                          radius 0.005
                        }
                      }
                    ]
                    boundingObject USE antennae_s2
                  }
                }
                DEF antennae_s1 Shape {
                  appearance USE antenna
                  geometry Capsule {
                    height 0.224
                    radius 0.0075
                  }
                }
              ]
              name "solid(1)"
              boundingObject USE antennae_s1
            }
          }
          DEF ShapeHead Transform {
            rotation 1 0 0 -1.5707953071795862
            children [
              Shape {
                appearance DEF AppHead PBRAppearance {
                  baseColor 0.3 0 0
                  roughness 0.5
                  metalness 0.1
                }
                geometry Capsule {
                  height 0.0088
                  radius 0.1
                }
              }
            ]
          }
        ]
        name "head"
        boundingObject USE ShapeHead
        physics Physics {
          density 600
          centerOfMass [
            0 0 0
          ]
        }
      }
    }
    DEF abdomen Hinge2Joint {
      jointParameters HingeJointParameters {
        position 0.5001115763950474
        axis 0 1 0
        anchor 0.4838 0 0
      }
      jointParameters2 JointParameters {
        position 2.298009140555453e-06
      }
      device [
        RotationalMotor {
          name "MotorAbdomenY"
          maxTorque 1000
        }
        PositionSensor {
          name "PSensorAbdomenY"
        }
      ]
      device2 [
        RotationalMotor {
          name "MotorAbdomenZ"
          maxTorque 1000
        }
        PositionSensor {
          name "PSensorAbdomenZ"
        }
      ]
      endPoint Solid {
        translation 0.5857653903056943 1.1804544258041833e-07 -0.05572330571389507
        rotation 1.9475877446397566e-06 -0.9999999999974633 1.131548468703283e-06 1.0706837307867498
        children [
          DEF ShapeAbdomen Transform {
            children [
              Shape {
                appearance DEF AppAbdomen PBRAppearance {
                  baseColor 0.05 0 0
                  roughness 0.2
                  metalness 0.2
                }
                geometry Capsule {
                  bottom FALSE
                  height 0.07445
                  radius 0.09343
                }
              }
              Transform {
                translation 0 0 -0.117
                rotation 0 1 0 3.14159
                children [
                  Shape {
                    appearance USE AppAbdomen
                    geometry Cone {
                      bottomRadius 0.0934
                      height 0.16
                    }
                  }
                ]
              }
            ]
          }
        ]
        name "abdomen"
        boundingObject Transform {
          translation 0 0 -0.03
          children [
            Shape {
              geometry Capsule {
                height 0.13
                radius 0.0934
                subdivision 16
              }
            }
          ]
        }
        physics Physics {
          density 600
        }
      }
    }
    DEF legFL Hinge2Joint {
      jointParameters HingeJointParameters {
        position 0.0969612455451173
        axis 0 0 1
        anchor 0.23902 -0.07 -0.02
      }
      jointParameters2 JointParameters {
        position 1.0268450806880866e-05
        axis 1 0 0
      }
      device [
        PositionSensor {
          name "PSensorLegLF1"
        }
        DEF motor1 RotationalMotor {
          name "MotorLegLF1"
          maxTorque 50
        }
      ]
      device2 [
        PositionSensor {
          name "PSensorLegLF2"
        }
        DEF motor2 RotationalMotor {
          name "MotorLegLF2"
          maxTorque 50
        }
      ]
      endPoint DEF solid Solid {
        translation 0.2399953996888659 -0.06990515566985935 -0.020000000658597927
        rotation -0.8919219880608574 0.3197489695452701 -0.31974327778439005 1.6849040055587958
        children [
          DEF coxa HingeJoint {
            jointParameters HingeJointParameters {
              position -0.320014293218888
              anchor 0 0 -0.02
            }
            device [
              DEF motor RotationalMotor {
                name "MotorLegLF3"
                maxTorque 50
              }
              PositionSensor {
                name "PSensorLegLF3"
              }
            ]
            endPoint DEF solid Solid {
              translation 0 -0.03774961538562586 -0.13390771061799653
              rotation -1 0 0 0.3200142932188878
              children [
                DEF femur HingeJoint {
                  jointParameters HingeJointParameters {
                    position 1.5600335754081764
                    anchor 0 0 -0.13
                  }
                  device [
                    DEF motor RotationalMotor {
                      name "MotorLegLF4"
                      maxTorque 50
                    }
                    PositionSensor {
                      name "PSensorLegLF4"
                    }
                  ]
                  endPoint DEF solid Solid {
                    translation 0 0.1039939765436385 -0.13111930453448115
                    rotation 1 0 0 1.5600335754081764
                    children [
                      DEF tibia HingeJoint {
                        jointParameters HingeJointParameters {
                          position 7.5230824959228625e-06
                          anchor 0 0 -0.104
                        }
                        device [
                          DEF motor RotationalMotor {
                            name "MotorLegLF5"
                            maxTorque 50
                          }
                          PositionSensor {
                            name "PSensorLegLF5"
                          }
                        ]
                        endPoint Solid {
                          translation 0 1.7946171074813034e-06 -0.2099999999846312
                          rotation 1 0 0 1.729924058778436e-05
                          children [
                            Solid {
                              translation 0 0 -0.11
                              children [
                                DEF TSensorLegLF TouchSensor {
                                  translation 5.33826328741327e-06 2.752634568442547e-05 3.910769708159734e-05
                                  rotation 0.9970211933415182 -0.07108789511266918 -0.029920748591995033 4.3911399828271653e-07
                                  name "TSensorLegLF"
                                  boundingObject Sphere {
                                    radius 0.01
                                  }
                                  physics Physics {
                                    density 20
                                    centerOfMass [
                                      0 0 0
                                    ]
                                  }
                                }
                                DEF ShapeClaw Shape {
                                  appearance DEF AppLeg PBRAppearance {
                                    baseColor 0 0 0
                                    roughness 0.5
                                    metalness 0.4
                                  }
                                  geometry Sphere {
                                    radius 0.0095
                                  }
                                }
                              ]
                              name "fl_tarsus_claw"
                              boundingObject USE ShapeClaw
                              physics Physics {
                              }
                            }
                            DEF ShapeFTarsus Shape {
                              appearance DEF AppLeg PBRAppearance {
                                baseColor 0 0 0
                                roughness 0.5
                                metalness 0.4
                              }
                              geometry Capsule {
                                height 0.19333
                                radius 0.00584
                              }
                            }
                          ]
                          name "fl_tarsus"
                          boundingObject USE ShapeFTarsus
                          physics Physics {
                          }
                        }
                      }
                      DEF ShapeFTibia Shape {
                        appearance DEF AppLeg PBRAppearance {
                          baseColor 0 0 0
                          roughness 0.5
                          metalness 0.4
                        }
                        geometry Capsule {
                          height 0.19346
                          radius 0.01095
                        }
                      }
                    ]
                    name "fl_tibia"
                    boundingObject USE ShapeFTibia
                    physics Physics {
                    }
                  }
                }
                DEF ShapeFFemur Shape {
                  appearance DEF AppLeg PBRAppearance {
                    baseColor 0 0 0
                    roughness 0.5
                    metalness 0.4
                  }
                  geometry Capsule {
                    height 0.2175
                    radius 0.0146
                  }
                }
              ]
              name "fl_femur"
              boundingObject USE ShapeFFemur
              physics Physics {
              }
            }
          }
          DEF ShapeFCoxa Shape {
            appearance DEF AppLeg PBRAppearance {
              baseColor 0 0 0
              roughness 0.5
              metalness 0.4
            }
            geometry Capsule {
              height 0.009
              radius 0.01095
            }
          }
        ]
        name "fl_coxa"
        boundingObject USE ShapeFCoxa
        physics Physics {
        }
      }
    }
    DEF legFR Hinge2Joint {
      jointParameters HingeJointParameters {
        position 0.09695071690031058
        axis 0 0 1
        anchor 0.23902 0.07 -0.02
      }
      jointParameters2 JointParameters {
        position 3.505842334775369e-05
        axis 1 0 0
      }
      device [
        DEF motor1 RotationalMotor {
          name "MotorLegRF1"
          maxTorque 50
        }
        PositionSensor {
          name "PSensorLegRF1"
        }
      ]
      device2 [
        PositionSensor {
          name "PSensorLegRF2"
        }
        DEF motor2 RotationalMotor {
          name "MotorLegRF2"
          maxTorque 50
        }
      ]
      endPoint DEF solid Solid {
        translation 0.2399953973782953 0.07009486808954858 -0.019999999999966853
        rotation -0.3167140950016383 0.670718079073443 -0.6706932536050471 2.5281343385409256
        children [
          DEF coxa HingeJoint {
            jointParameters HingeJointParameters {
              position -0.3465448076141345
              anchor 0 0 -0.02
            }
            device [
              DEF motor RotationalMotor {
                name "MotorLegRF3"
                maxTorque 50
              }
              PositionSensor {
                name "PSensorLegRF3"
              }
            ]
            endPoint DEF solid Solid {
              translation 2.2204460492499403e-16 -0.040758006438331704 -0.1328662257327858
              rotation -1 0 0 0.3465448076141346
              children [
                DEF femur HingeJoint {
                  jointParameters HingeJointParameters {
                    position 1.586554736028222
                    anchor 0 0 -0.13
                  }
                  device [
                    DEF motor RotationalMotor {
                      name "MotorLegRF4"
                      maxTorque 50
                    }
                    PositionSensor {
                      name "PSensorLegRF4"
                    }
                  ]
                  endPoint DEF solid Solid {
                    translation -4.237176950638817e-06 0.10397427263488712 -0.1283608601318349
                    rotation 0.9999999999992708 8.335076095797454e-07 8.738461376163608e-07 1.58655515997423
                    children [
                      DEF tibia HingeJoint {
                        jointParameters HingeJointParameters {
                          position 1.3931458251858635e-06
                          anchor 0 0 -0.104
                        }
                        device [
                          DEF motor RotationalMotor {
                            name "MotorLegRF5"
                            maxTorque 50
                          }
                          PositionSensor {
                            name "PSensorLegRF5"
                          }
                        ]
                        endPoint Solid {
                          translation 0 1.4561666305451284e-07 -0.20999999999989816
                          rotation 1 0 0 1.3930792680407141e-06
                          children [
                            Solid {
                              translation 0 0 -0.106
                              children [
                                DEF TSensorLegRF TouchSensor {
                                  translation -1.9119265542988373e-06 -1.1699756146121842e-06 7.1375960766228985e-06
                                  rotation 0.6886980366011419 0.7131688308154426 0.1307104935920092 5.620054732018966e-08
                                  name "TSensorLegRF"
                                  boundingObject Sphere {
                                    radius 0.01
                                  }
                                  physics Physics {
                                    density 20
                                    centerOfMass [
                                      0 0 0
                                    ]
                                  }
                                }
                                DEF ShapeClaw Shape {
                                  appearance USE AppLeg
                                  geometry Sphere {
                                    radius 0.0095
                                  }
                                }
                              ]
                              name "fl_tarsus_claw"
                              boundingObject USE ShapeClaw
                              physics Physics {
                              }
                            }
                            DEF ShapeFTarsus Shape {
                              appearance DEF AppLeg PBRAppearance {
                                baseColor 0 0 0
                                roughness 0.5
                                metalness 0.4
                              }
                              geometry Capsule {
                                height 0.19333
                                radius 0.00584
                              }
                            }
                            TouchSensor {
                              translation 0 0 -0.106
                              name "TSensorLegFR"
                              boundingObject USE ShapeClaw
                            }
                          ]
                          name "fl_tarsus"
                          boundingObject USE ShapeFTarsus
                          physics Physics {
                          }
                        }
                      }
                      DEF ShapeFTibia Shape {
                        appearance USE AppLeg
                        geometry Capsule {
                          height 0.19346
                          radius 0.01095
                        }
                      }
                    ]
                    name "fl_tibia"
                    boundingObject USE ShapeFTibia
                    physics Physics {
                    }
                  }
                }
                DEF ShapeFFemur Shape {
                  appearance USE AppLeg
                  geometry Capsule {
                    height 0.2175
                    radius 0.0146
                  }
                }
              ]
              name "fl_femur"
              boundingObject USE ShapeFFemur
              physics Physics {
              }
            }
          }
          DEF ShapeFCoxa Shape {
            appearance USE AppLeg
            geometry Capsule {
              height 0.009
              radius 0.01095
            }
          }
        ]
        name "fr_coxa"
        boundingObject USE ShapeFCoxa
        physics Physics {
        }
      }
    }
    DEF legML Hinge2Joint {
      jointParameters HingeJointParameters {
        position -0.09694641318058558
        axis 0 0 1
        anchor 0.34 -0.02 -0.02
      }
      jointParameters2 JointParameters {
        position -0.0017208619184034923
        axis 1 0 0
      }
      device [
        DEF motor1 RotationalMotor {
          name "MotorLegLM1"
          maxTorque 50
        }
        PositionSensor {
          name "PSensorLegLM1"
        }
      ]
      device2 [
        DEF motor2 RotationalMotor {
          name "MotorLegLM2"
          maxTorque 50
        }
        PositionSensor {
          name "PSensorLegLM2"
        }
      ]
      endPoint DEF solid Solid {
        translation 0.34726947852552964 -0.05086397990420276 -0.02994875862406221
        rotation -0.9976589497053201 0.048397599521317274 -0.048314515763398284 1.5748599575437205
        children [
          DEF ShapeMCoxa Shape {
            appearance USE AppLeg
            geometry Capsule {
              height 0.0146
              radius 0.0219
            }
          }
          DEF coxa HingeJoint {
            jointParameters HingeJointParameters {
              position -0.411612558534984
              anchor 0 0 -0.027
            }
            device [
              DEF motor RotationalMotor {
                name "MotorLegLM3"
                maxTorque 50
              }
              PositionSensor {
                name "PSensorLegLM3"
              }
            ]
            endPoint DEF solid Solid {
              translation 0 -0.05735030974434723 -0.16332793018575717
              rotation -1 0 0 0.41161255853498385
              children [
                DEF ShapeMFemur Shape {
                  appearance USE AppLeg
                  geometry Capsule {
                    height 0.26
                    radius 0.0146
                  }
                }
                DEF femur HingeJoint {
                  jointParameters HingeJointParameters {
                    position 1.4144561636208406
                    anchor 0 0 -0.147
                  }
                  device [
                    DEF motor RotationalMotor {
                      name "MotorLegLM4"
                      maxTorque 50
                    }
                    PositionSensor {
                      name "PSensorLegLM4"
                    }
                  ]
                  endPoint DEF solid Solid {
                    translation 0 0.12149986113433588 -0.16615159900210513
                    rotation 0.9999999999999999 0 0 1.4144561636208406
                    children [
                      DEF ShapeMTibia Shape {
                        appearance USE AppLeg
                        geometry Capsule {
                          height 0.22074
                          radius 0.01095
                        }
                      }
                      DEF tibia HingeJoint {
                        jointParameters HingeJointParameters {
                          position -3.3603131426895933e-05
                          anchor 0 0 -0.121
                        }
                        device [
                          DEF motor RotationalMotor {
                            name "MotorLegLM5"
                            maxTorque 50
                          }
                          PositionSensor {
                            name "PSensorLegLM5"
                          }
                        ]
                        endPoint Solid {
                          translation 0 -3.893179864108227e-06 -0.2529999999425959
                          rotation -1 0 0 2.9531319604882526e-05
                          children [
                            DEF ShapeMTarsus Shape {
                              appearance USE AppLeg
                              geometry Capsule {
                                height 0.254
                                radius 0.0059
                              }
                            }
                            Solid {
                              translation 0 0 -0.14
                              children [
                                DEF TSensorLegLM TouchSensor {
                                  translation 3.4632061240991163e-06 -2.6389960726458384e-05 2.8171681725308595e-05
                                  rotation -0.9242444135183645 -0.3340920912516323 -0.18481000688059523 6.145893188166911e-08
                                  name "TSensorLegLM"
                                  boundingObject Sphere {
                                    radius 0.01
                                  }
                                  physics Physics {
                                    density 20
                                    centerOfMass [
                                      0 0 0
                                    ]
                                  }
                                }
                                DEF ShapeClaw Shape {
                                  appearance USE AppLeg
                                  geometry Sphere {
                                    radius 0.0095
                                  }
                                }
                              ]
                              name "fl_tarsus_claw"
                              boundingObject USE ShapeClaw
                              physics Physics {
                              }
                            }
                            DEF t_sensor TouchSensor {
                              translation 0 0 -0.14
                              name "TSensorLegML"
                              boundingObject USE ShapeClaw
                            }
                          ]
                          boundingObject USE ShapeMTarsus
                          physics Physics {
                          }
                        }
                      }
                    ]
                    boundingObject USE ShapeMTibia
                    physics Physics {
                    }
                  }
                }
              ]
              boundingObject USE ShapeMFemur
              physics Physics {
              }
            }
          }
        ]
        boundingObject USE ShapeMCoxa
        physics Physics {
        }
      }
    }
    DEF legMR Hinge2Joint {
      jointParameters HingeJointParameters {
        position -0.0969496442508356
        axis 0 0 1
        anchor 0.34 0.02 -0.02
      }
      jointParameters2 JointParameters {
        position 0.0002632102527708041
        axis 1 0 0
      }
      device [
        DEF motor1 RotationalMotor {
          name "MotorLegRM1"
          maxTorque 50
        }
        PositionSensor {
          name "PSensorLegRM1"
        }
      ]
      device2 [
        DEF motor2 RotationalMotor {
          name "MotorLegRM2"
          maxTorque 50
        }
        PositionSensor {
          name "PSensorLegRM2"
        }
      ]
      endPoint DEF solid Solid {
        translation 0.35285720223362493 0.04889347135809273 -0.029992980716632534
        rotation 0.034287848582828635 0.7067844798110615 -0.7065975109903575 3.210121770799896
        children [
          DEF ShapeMCoxa Shape {
            appearance USE AppLeg
            geometry Capsule {
              height 0.0146
              radius 0.0219
            }
          }
          DEF coxa HingeJoint {
            jointParameters HingeJointParameters {
              position -0.3851009169988125
              anchor 0 0 -0.027
            }
            device [
              DEF motor RotationalMotor {
                name "MotorLegRM3"
                maxTorque 50
              }
              PositionSensor {
                name "PSensorLegRM3"
              }
            ]
            endPoint DEF solid Solid {
              translation 0 -0.05747639228939621 -0.16480172986132813
              rotation -1 0 0 0.385100916998813
              children [
                DEF ShapeMFemur Shape {
                  appearance USE AppLeg
                  geometry Capsule {
                    height 0.26
                    radius 0.0146
                  }
                }
                DEF femur HingeJoint {
                  jointParameters HingeJointParameters {
                    position 1.3879284675068468
                    anchor 0 0 -0.147
                  }
                  device [
                    DEF motor RotationalMotor {
                      name "MotorLegRM4"
                      maxTorque 50
                    }
                    PositionSensor {
                      name "PSensorLegRM4"
                    }
                  ]
                  endPoint DEF solid Solid {
                    translation 0 0.1209491245573706 -0.169367594166685
                    rotation 1 0 0 1.3879284675068466
                    children [
                      DEF ShapeMTibia Shape {
                        appearance USE AppLeg
                        geometry Capsule {
                          height 0.22074
                          radius 0.01095
                        }
                      }
                      DEF tibia HingeJoint {
                        jointParameters HingeJointParameters {
                          position -3.637136962771783e-05
                          anchor 0 0 -0.121
                        }
                        device [
                          DEF motor RotationalMotor {
                            name "MotorLegRM5"
                            maxTorque 50
                          }
                          PositionSensor {
                            name "PSensorLegRM5"
                          }
                        ]
                        endPoint Solid {
                          translation 0 -4.801020789803673e-06 -0.2529999999126926
                          rotation -1 0 0 3.6371374996763e-05
                          children [
                            DEF ShapeMTarsus Shape {
                              appearance USE AppLeg
                              geometry Capsule {
                                height 0.254
                                radius 0.0059
                              }
                            }
                            Solid {
                              translation 0 0 -0.14
                              children [
                                DEF TSensorLegRM TouchSensor {
                                  translation 2.082013340354294e-05 -4.249443460996316e-05 4.790540610510874e-05
                                  rotation -0.2804956421423864 -0.771064547978737 -0.5716481939003011 2.3551542909329292e-07
                                  name "TSensorLegRM"
                                  boundingObject Sphere {
                                    radius 0.01
                                  }
                                  physics Physics {
                                    density 20
                                    centerOfMass [
                                      0 0 0
                                    ]
                                  }
                                }
                                DEF ShapeClaw Shape {
                                  appearance USE AppLeg
                                  geometry Sphere {
                                    radius 0.0095
                                  }
                                }
                              ]
                              name "fl_tarsus_claw"
                              boundingObject USE ShapeClaw
                              physics Physics {
                              }
                            }
                            TouchSensor {
                              name "TSensorLegMR"
                            }
                          ]
                          boundingObject USE ShapeMTarsus
                          physics Physics {
                          }
                        }
                      }
                    ]
                    boundingObject USE ShapeMTibia
                    physics Physics {
                    }
                  }
                }
              ]
              boundingObject USE ShapeMFemur
              physics Physics {
              }
            }
          }
        ]
        name "solid(1)"
        boundingObject USE ShapeMCoxa
        physics Physics {
        }
      }
    }
    DEF legHL Hinge2Joint {
      jointParameters HingeJointParameters {
        position 0.09694661631563235
        axis 0 0 1
        anchor 0.426276 -0.03 -0.0340389
      }
      jointParameters2 JointParameters {
        position -1.3278050812575968e-05
        axis 1 0 0
      }
      device [
        DEF motor1 RotationalMotor {
          name "MotorLegLH1"
          maxTorque 50
        }
        PositionSensor {
          name "PSensorLegLH1"
        }
      ]
      device2 [
        DEF motor2 RotationalMotor {
          name "MotorLegLH2"
          maxTorque 50
        }
        PositionSensor {
          name "PSensorLegLH2"
        }
      ]
      endPoint DEF solid Solid {
        translation 0.4338543064504001 -0.06945170998306716 -0.029999996687689677
        rotation -0.8316127596548735 -0.39269527692982614 0.392696622669731 1.754164629534442
        children [
          DEF ShapeHCoxa Shape {
            appearance USE AppLeg
            geometry Capsule {
              height 0.04926
              radius 0.0219
            }
          }
          DEF coxa HingeJoint {
            jointParameters HingeJointParameters {
              position -0.7780718115134728
              anchor 0 0 -0.046
            }
            device [
              DEF motor RotationalMotor {
                name "MotorLegLH3"
                maxTorque 50
              }
              PositionSensor {
                name "PSensorLegLH3"
              }
            ]
            endPoint DEF solid Solid {
              translation 0 -0.12915095007903865 -0.17705736184461046
              rotation -1 0 0 0.7780718115134727
              children [
                DEF ShapeHFemur Shape {
                  appearance USE AppLeg
                  geometry Capsule {
                    height 0.336
                    radius 0.0146
                  }
                }
                DEF femur HingeJoint {
                  jointParameters HingeJointParameters {
                    position 1.8069888191323424
                    anchor 0 0 -0.184
                  }
                  device [
                    DEF motor RotationalMotor {
                      name "MotorLegLH4"
                      maxTorque 50
                    }
                    PositionSensor {
                      name "PSensorLegLH4"
                    }
                  ]
                  endPoint DEF solid Solid {
                    translation 0 0.1575022298043025 -0.1460915892357345
                    rotation 1 0 0 1.8069888191323422
                    children [
                      DEF ShapeHTibia Shape {
                        appearance USE AppLeg
                        geometry Capsule {
                          height 0.3
                          radius 0.01095
                        }
                      }
                      DEF tibia HingeJoint {
                        jointParameters HingeJointParameters {
                          position 8.4193908145065e-06
                          anchor 0 0 -0.161
                        }
                        device [
                          DEF motor RotationalMotor {
                            name "MotorLegLH5"
                            maxTorque 50
                          }
                          PositionSensor {
                            name "PSensorLegLH5"
                          }
                        ]
                        endPoint Solid {
                          translation 0 2.1450034676749304e-06 -0.33599999998685287
                          rotation 1 0 0 8.419406621300065e-06
                          children [
                            DEF ShapeHTarsus Shape {
                              appearance USE AppLeg
                              geometry Capsule {
                                height 0.339
                                radius 0.0059
                              }
                            }
                            Solid {
                              translation 0 0 -0.18
                              children [
                                DEF TSensorLegLH TouchSensor {
                                  translation -2.0716497707184978e-05 -2.3382125986959323e-05 3.6025591578781047e-06
                                  rotation -0.4418803033671764 0.7631655736677062 0.4715083293692415 1.8772823779701294e-07
                                  name "TSensorLegLH"
                                  boundingObject Sphere {
                                    radius 0.01
                                  }
                                  physics Physics {
                                    density 20
                                    centerOfMass [
                                      0 0 0
                                    ]
                                  }
                                }
                                DEF ShapeClaw Shape {
                                  appearance USE AppLeg
                                  geometry Sphere {
                                    radius 0.0095
                                  }
                                }
                              ]
                              name "fl_tarsus_claw"
                              boundingObject USE ShapeClaw
                              physics Physics {
                              }
                            }
                            DEF t_sensor TouchSensor {
                              translation 0 0 -0.18
                              name "TSensorLegHL"
                              boundingObject USE ShapeClaw
                            }
                          ]
                          boundingObject USE ShapeHTarsus
                          physics Physics {
                          }
                        }
                      }
                    ]
                    boundingObject USE ShapeHTibia
                    physics Physics {
                    }
                  }
                }
              ]
              boundingObject USE ShapeHFemur
              physics Physics {
              }
            }
          }
        ]
        name "solid(2)"
        boundingObject USE ShapeHCoxa
        physics Physics {
        }
      }
    }
    DEF legHR Hinge2Joint {
      jointParameters HingeJointParameters {
        position 0.09695980380049422
        axis 0 0 1
        anchor 0.426276 0.03 -0.0340389
      }
      jointParameters2 JointParameters {
        position 6.654578521061495e-06
        axis 1 0 0
      }
      device [
        DEF motor1 RotationalMotor {
          name "MotorLegRH1"
          maxTorque 50
        }
        PositionSensor {
          name "PSensorLegRH1"
        }
      ]
      device2 [
        DEF motor2 RotationalMotor {
          name "MotorLegRH2"
          maxTorque 50
        }
        PositionSensor {
          name "PSensorLegRH2"
        }
      ]
      endPoint DEF solid Solid {
        translation 0.42611018073149115 0.07017273732209814 -0.03000100831868361
        rotation -0.24571812118858363 -0.6854307443444703 0.685424904440259 2.6597030397722268
        children [
          DEF ShapeHCoxa Shape {
            appearance USE AppLeg
            geometry Capsule {
              height 0.04926
              radius 0.0219
            }
          }
          DEF coxa HingeJoint {
            jointParameters HingeJointParameters {
              position -0.8045219608796892
              anchor 0 0 -0.046
            }
            device [
              DEF motor RotationalMotor {
                name "MotorLegRH3"
                maxTorque 50
              }
              PositionSensor {
                name "PSensorLegRH3"
              }
            ]
            endPoint DEF solid Solid {
              translation -6.333731270568978e-07 -0.13258075303115055 -0.17359416065343936
              rotation -0.9999999999997986 5.992609152750523e-07 2.0886271353514652e-07 0.8045219608823141
              children [
                DEF ShapeHFemur Shape {
                  appearance USE AppLeg
                  geometry Capsule {
                    height 0.336
                    radius 0.0146
                  }
                }
                DEF femur HingeJoint {
                  jointParameters HingeJointParameters {
                    position 1.8335201620704955
                    anchor 0 0 -0.184
                  }
                  device [
                    DEF motor RotationalMotor {
                      name "MotorLegRH4"
                      maxTorque 50
                    }
                    PositionSensor {
                      name "PSensorLegRH4"
                    }
                  ]
                  endPoint DEF solid Solid {
                    translation 0 0.15644115613289156 -0.14192667510399348
                    rotation 1 0 0 1.8335201620704955
                    children [
                      DEF ShapeHTibia Shape {
                        appearance USE AppLeg
                        geometry Capsule {
                          height 0.3
                          radius 0.01095
                        }
                      }
                      DEF tibia HingeJoint {
                        jointParameters HingeJointParameters {
                          position 1.4971045132739065e-07
                          anchor 0 0 -0.161
                        }
                        device [
                          DEF motor RotationalMotor {
                            name "MotorLegRH5"
                            maxTorque 50
                          }
                          PositionSensor {
                            name "PSensorLegRH5"
                          }
                        ]
                        endPoint Solid {
                          translation 0 7.855690879425957e-09 -0.3360000000074427
                          rotation 1 0 0 1.490116119384766e-07
                          children [
                            DEF ShapeHTarsus Shape {
                              appearance USE AppLeg
                              geometry Capsule {
                                height 0.339
                                radius 0.0059
                              }
                            }
                            Solid {
                              translation 0 0 -0.18
                              children [
                                DEF TSensorLegRH TouchSensor {
                                  translation -8.116884586684137e-08 -3.7559027830091907e-06 -3.475058192869973e-06
                                  rotation -0.4327103160987529 -0.7644844026770431 -0.477834051115282 2.4829711469267317e-11
                                  name "TSensorLegRH"
                                  boundingObject Sphere {
                                    radius 0.01
                                  }
                                  physics Physics {
                                    density 20
                                    centerOfMass [
                                      0 0 0
                                    ]
                                  }
                                }
                                DEF ShapeClaw Shape {
                                  appearance USE AppLeg
                                  geometry Sphere {
                                    radius 0.0095
                                  }
                                }
                              ]
                              name "fl_tarsus_claw"
                              boundingObject USE ShapeClaw
                              physics Physics {
                              }
                            }
                            DEF t_sensor TouchSensor {
                              translation 0 0 -0.18
                              name "TSensorLegHR"
                              boundingObject USE ShapeClaw
                            }
                          ]
                          boundingObject USE ShapeHTarsus
                          physics Physics {
                          }
                        }
                      }
                    ]
                    boundingObject USE ShapeHTibia
                    physics Physics {
                    }
                  }
                }
              ]
              boundingObject USE ShapeHFemur
              physics Physics {
              }
            }
          }
        ]
        name "solid(3)"
        boundingObject USE ShapeHCoxa
        physics Physics {
        }
      }
    }
    DEF thorax Transform {
      translation 0.19 0 0
      rotation 0 1 0 -1.5707953071795862
      children [
        DEF ShapeThorax Shape {
          appearance USE AppLeg
          geometry Capsule {
            height 0.05839
            radius 0.06642
          }
        }
      ]
    }
    DEF petiole Transform {
      translation 0.368 0 0
      rotation 0 1 0 1.5708
      children [
        DEF ShapePetiole Shape {
          appearance USE AppLeg
          geometry Capsule {
            height 0.084
            radius 0.04
          }
        }
      ]
    }
    Pen {
      translation 0 0 -0.19
      inkColor 0.9411764740943909 0.6078431606292725 0.0941176488995552
      inkDensity 1
    }
    Transform {
      translation 0.09 0 -0.00999954
      rotation 0 1 0 -1.5707953071795862
      children [
        Shape {
          appearance USE AppLeg
          geometry Cone {
            bottomRadius 0.03
            height 0.03
          }
        }
      ]
    }
    Transform {
      translation 0.45 0 -0.0099999
      rotation 0 1 0 -1.5707953071795862
      children [
        Shape {
          appearance USE AppLeg
          geometry Cone {
            bottomRadius 0.02
            height 0.07
          }
        }
      ]
    }
  ]
  name "desert_ant"
  boundingObject Transform {
    translation 0.274 0 0
    rotation 0 1 0 1.5708
    children [
      Shape {
        geometry Cylinder {
          height 0.36
          radius 0.065
        }
      }
    ]
  }
  physics Physics {
    density 600
  }
  controller "I2Bot"
  supervisor TRUE
  window "AIBot"
}
