#VRML_SIM R2023a utf8

EXTERNPROTO "https://raw.githubusercontent.com/cyberbotics/webots/R2023a/projects/objects/backgrounds/protos/TexturedBackground.proto"
EXTERNPROTO "https://raw.githubusercontent.com/cyberbotics/webots/R2023a/projects/objects/backgrounds/protos/TexturedBackgroundLight.proto"

WorldInfo {
  basicTimeStep 8
}
Viewpoint {
  orientation 0.5457221845804616 -0.008558316702284336 -0.8379224620882004 3.167867485197528
  position 2.3095033378198946 -0.8027467966748854 5.082581539767725
}
TexturedBackground {
  skybox FALSE
  skyColor [
    0.462745 0.462745 0.462745
  ]
}
TexturedBackgroundLight {
}
DEF ant Robot {
  translation 0 0 0.433843
  children [
    DEF head Hinge2Joint {
      jointParameters HingeJointParameters {
        position -0.2000110061694734
        axis 0 1 0
        anchor 0.1 0 0
      }
      jointParameters2 JointParameters {
        position 6.656098762948745e-07
      }
      device [
        RotationalMotor {
          name "MotorHeadY"
          maxTorque 1000
        }
        PositionSensor {
          name "PSensorHeadY"
        }
      ]
      device2 [
        RotationalMotor {
          name "MotorHeadZ"
          maxTorque 1000
        }
        PositionSensor {
          name "PSensorHeadZ"
        }
      ]
      endPoint Solid {
        translation -0.007808008555164739 -2.4521298248704267e-06 -0.021856230959913465
        rotation 0 1 0 0
        children [
          DEF left_eye Camera {
            translation -0.0586601 -0.0770091 0.0625
            rotation -0.10124704903090816 0.012681806141418225 -0.9947804817423411 2.6381
            children [
              DEF left_eye Transform {
                translation -0.02 0 -0.01
                rotation 0 1 0 0
                children [
                  Shape {
                    appearance PBRAppearance {
                      baseColor 0 0 0
                    }
                    geometry Sphere {
                      radius 0.026
                    }
                  }
                ]
              }
            ]
            name "left_camera"
            boundingObject USE left_eye
            fieldOfView 2
            width 74
            height 19
            projection "cylindrical"
          }
          DEF right_eye Camera {
            translation -0.0586601 0.0770091 0.0625
            rotation 0.0944626446130286 0.03982601880912104 0.9947314697939985 2.60314
            children [
              DEF right_eye Transform {
                translation -0.02 0 -0.01
                rotation 0 1 0 0
                children [
                  Shape {
                    appearance PBRAppearance {
                      baseColor 0 0 0
                    }
                    geometry Sphere {
                      radius 0.026
                    }
                  }
                ]
              }
            ]
            name "right_camera"
            boundingObject USE right_eye
            fieldOfView 2
            width 74
            height 19
          }
          DEF abstract_eye Camera {
            translation 0 0 0.3
            rotation 0 1 0 -1.5707953071795862
            fieldOfView 3.1415
            width 78
            height 78
            projection "spherical"
          }
          DEF left_antenna Hinge2Joint {
            jointParameters HingeJointParameters {
              position -0.4
              axis 0 1 0
              anchor -0.0845 -0.04 0.02
            }
            jointParameters2 JointParameters {
              position 0.8956685134750993
            }
            device [
              RotationalMotor {
                name "MotorAntennaeL1"
              }
              PositionSensor {
                name "PSensorAntennaeL1"
              }
            ]
            device2 [
              RotationalMotor {
                name "MotorAntennaeL2"
              }
              PositionSensor {
                name "PSensorAntennaeL2"
              }
            ]
            endPoint Solid {
              translation -0.15098878160907753 -0.13016242711112203 -0.008111005986480579
              rotation -0.5468708367986387 0.7546573060896906 0.36252536218119635 1.4415390639574202
              children [
                HingeJoint {
                  jointParameters HingeJointParameters {
                    position 1
                    anchor 0 0 -0.12
                  }
                  device [
                    RotationalMotor {
                      name "MotorAntennaeL3"
                    }
                    PositionSensor {
                      name "PSensorAntennaeL3"
                    }
                  ]
                  endPoint Solid {
                    translation 0 0.13776983698767287 -0.20846099502826118
                    rotation 1 0 0 0.9999999999999998
                    children [
                      DEF OSensorL Transform {
                        translation 0 0 -0.16
                      }
                      Receiver {
                        translation 0 0 -0.16
                        name "OSensorL"
                        model "OSensorL"
                        channel 11
                      }
                      DistanceSensor {
                        translation 0 0 -0.15
                        name "DSensorL"
                        type "infra-red"
                      }
                      DEF antennae_s2 Shape {
                        appearance DEF antenna PBRAppearance {
                          baseColor 0 0 0
                          roughness 0.2
                          metalness 0.4
                        }
                        geometry Capsule {
                          height 0.317
                          radius 0.005
                        }
                      }
                    ]
                    boundingObject USE antennae_s2
                  }
                }
                DEF antennae_s1 Shape {
                  appearance USE antenna
                  geometry Capsule {
                    height 0.224
                    radius 0.0075
                  }
                }
              ]
              boundingObject USE antennae_s1
            }
          }
          DEF right_antenna Hinge2Joint {
            jointParameters HingeJointParameters {
              position -0.4
              axis 0 1 0
              anchor -0.083 0.04 0.02
            }
            jointParameters2 JointParameters {
              position -0.704575528517515
            }
            device [
              RotationalMotor {
                name "MotorAntennaeR1"
              }
              PositionSensor {
                name "PSensorAntennaeR1"
              }
            ]
            device2 [
              RotationalMotor {
                name "MotorAntennaeR2"
              }
              PositionSensor {
                name "PSensorAntennaeR2"
              }
            ]
            endPoint Solid {
              translation -0.16187602421591096 0.11280265893895922 -0.013348248159514135
              rotation 0.4617022161403876 0.8325589772275247 -0.3060663539968302 1.344883827706382
              children [
                HingeJoint {
                  jointParameters HingeJointParameters {
                    position -1
                    anchor 0 0 -0.12
                  }
                  device [
                    RotationalMotor {
                      name "MotorAntennaeR3"
                    }
                    PositionSensor {
                      name "PSensorAntennaeR3"
                    }
                  ]
                  endPoint Solid {
                    translation 0 -0.13776983698767287 -0.20846099502826118
                    rotation -1 0 0 0.9999999999999998
                    children [
                      DEF OSensorR Transform {
                        translation 0 0 -0.16
                      }
                      Receiver {
                        translation 0 0 -0.16
                        name "OSensorR"
                        model "OSensorR"
                        channel 12
                      }
                      DistanceSensor {
                        translation 0 0 -0.15
                        name "DSensorR"
                        type "infra-red"
                      }
                      DEF antennae_s2 Shape {
                        appearance USE antenna
                        geometry Capsule {
                          height 0.317
                          radius 0.005
                        }
                      }
                    ]
                    boundingObject USE antennae_s2
                  }
                }
                DEF antennae_s1 Shape {
                  appearance USE antenna
                  geometry Capsule {
                    height 0.224
                    radius 0.0075
                  }
                }
              ]
              name "solid(1)"
              boundingObject USE antennae_s1
            }
          }
          DEF ShapeHead Transform {
            rotation 1 0 0 -1.5707953071795862
            children [
              Shape {
                appearance DEF AppHead PBRAppearance {
                  baseColor 0.3 0 0
                  roughness 0.5
                  metalness 0.1
                }
                geometry Capsule {
                  height 0.0088
                  radius 0.1
                }
              }
            ]
          }
        ]
        name "head"
        boundingObject USE ShapeHead
        physics Physics {
          density 600
          centerOfMass [
            0 0 0
          ]
        }
      }
    }
    DEF abdomen Hinge2Joint {
      jointParameters HingeJointParameters {
        position 0.5001168737560294
        axis 0 1 0
        anchor 0.4838 0 0
      }
      jointParameters2 JointParameters {
        position 2.328791822804674e-06
      }
      device [
        RotationalMotor {
          name "MotorAbdomenY"
          maxTorque 1000
        }
        PositionSensor {
          name "PSensorAbdomenY"
        }
      ]
      device2 [
        RotationalMotor {
          name "MotorAbdomenZ"
          maxTorque 1000
        }
        PositionSensor {
          name "PSensorAbdomenZ"
        }
      ]
      endPoint Solid {
        translation 0.585765095117795 1.2162233563315718e-07 -0.05572384586059147
        rotation 1.9735495771824797e-06 -0.9999999999973949 1.1469397309151305e-06 1.070678433425827
        children [
          DEF ShapeAbdomen Transform {
            children [
              Shape {
                appearance DEF AppAbdomen PBRAppearance {
                  baseColor 0.05 0 0
                  roughness 0.2
                  metalness 0.2
                }
                geometry Capsule {
                  bottom FALSE
                  height 0.07445
                  radius 0.09343
                }
              }
              Transform {
                translation 0 0 -0.117
                rotation 0 1 0 3.14159
                children [
                  Shape {
                    appearance USE AppAbdomen
                    geometry Cone {
                      bottomRadius 0.0934
                      height 0.16
                    }
                  }
                ]
              }
            ]
          }
        ]
        name "abdomen"
        boundingObject Transform {
          translation 0 0 -0.03
          children [
            Shape {
              geometry Capsule {
                height 0.13
                radius 0.0934
                subdivision 16
              }
            }
          ]
        }
        physics Physics {
          density 600
        }
      }
    }
    DEF legFL Hinge2Joint {
      jointParameters HingeJointParameters {
        position 0.09696323126718868
        axis 0 0 1
        anchor 0.23902 -0.07 -0.02
      }
      jointParameters2 JointParameters {
        position 2.2432628469450883e-06
        axis 1 0 0
      }
      device [
        PositionSensor {
          name "PSensorLegLF1"
        }
        DEF motor1 RotationalMotor {
          name "MotorLegLF1"
          maxTorque 50
        }
      ]
      device2 [
        PositionSensor {
          name "PSensorLegLF2"
        }
        DEF motor2 RotationalMotor {
          name "MotorLegLF2"
          maxTorque 50
        }
      ]
      endPoint DEF solid Solid {
        translation 0.23999539950053003 -0.0699051537329921 -0.02000000065836515
        rotation -0.8919232610550917 0.3197455706008443 -0.31974312575877434 1.6849102464443333
        children [
          DEF coxa HingeJoint {
            jointParameters HingeJointParameters {
              position -0.3200179646534062
              anchor 0 0 -0.02
            }
            device [
              DEF motor RotationalMotor {
                name "MotorLegLF3"
                maxTorque 50
              }
              PositionSensor {
                name "PSensorLegLF3"
              }
            ]
            endPoint DEF solid Solid {
              translation 0 -0.037750033590072174 -0.13390757202198775
              rotation -1 0 0 0.32001796465340576
              children [
                DEF femur HingeJoint {
                  jointParameters HingeJointParameters {
                    position 1.560034686858253
                    anchor 0 0 -0.13
                  }
                  device [
                    DEF motor RotationalMotor {
                      name "MotorLegLF4"
                      maxTorque 50
                    }
                    PositionSensor {
                      name "PSensorLegLF4"
                    }
                  ]
                  endPoint DEF solid Solid {
                    translation 0 0.10399397778762536 -0.13111918895036725
                    rotation 1 0 0 1.560034686858253
                    children [
                      DEF tibia HingeJoint {
                        jointParameters HingeJointParameters {
                          position 6.867649698322169e-06
                          anchor 0 0 -0.104
                        }
                        device [
                          DEF motor RotationalMotor {
                            name "MotorLegLF5"
                            maxTorque 50
                          }
                          PositionSensor {
                            name "PSensorLegLF5"
                          }
                        ]
                        endPoint Solid {
                          translation 0 1.7251412309452058e-06 -0.2099999999857728
                          rotation 1 0 0 1.6643816625315536e-05
                          children [
                            Solid {
                              translation 0 0 -0.11
                              children [
                                DEF TSensorLegLF TouchSensor {
                                  translation 7.525277188502599e-06 2.579183314305178e-05 4.207748217116558e-05
                                  rotation 0.9918606998152059 -0.11872173135857644 -0.04601633041988341 4.344966677446648e-07
                                  name "TSensorLegLF"
                                  boundingObject Sphere {
                                    radius 0.01
                                  }
                                  physics Physics {
                                    density 20
                                    centerOfMass [
                                      0 0 0
                                    ]
                                  }
                                }
                                DEF ShapeClaw Shape {
                                  appearance DEF AppLeg PBRAppearance {
                                    baseColor 0 0 0
                                    roughness 0.5
                                    metalness 0.4
                                  }
                                  geometry Sphere {
                                    radius 0.0095
                                  }
                                }
                              ]
                              name "fl_tarsus_claw"
                              boundingObject USE ShapeClaw
                              physics Physics {
                              }
                            }
                            DEF ShapeFTarsus Shape {
                              appearance DEF AppLeg PBRAppearance {
                                baseColor 0 0 0
                                roughness 0.5
                                metalness 0.4
                              }
                              geometry Capsule {
                                height 0.19333
                                radius 0.00584
                              }
                            }
                          ]
                          name "fl_tarsus"
                          boundingObject USE ShapeFTarsus
                          physics Physics {
                          }
                        }
                      }
                      DEF ShapeFTibia Shape {
                        appearance DEF AppLeg PBRAppearance {
                          baseColor 0 0 0
                          roughness 0.5
                          metalness 0.4
                        }
                        geometry Capsule {
                          height 0.19346
                          radius 0.01095
                        }
                      }
                    ]
                    name "fl_tibia"
                    boundingObject USE ShapeFTibia
                    physics Physics {
                    }
                  }
                }
                DEF ShapeFFemur Shape {
                  appearance DEF AppLeg PBRAppearance {
                    baseColor 0 0 0
                    roughness 0.5
                    metalness 0.4
                  }
                  geometry Capsule {
                    height 0.2175
                    radius 0.0146
                  }
                }
              ]
              name "fl_femur"
              boundingObject USE ShapeFFemur
              physics Physics {
              }
            }
          }
          DEF ShapeFCoxa Shape {
            appearance DEF AppLeg PBRAppearance {
              baseColor 0 0 0
              roughness 0.5
              metalness 0.4
            }
            geometry Capsule {
              height 0.009
              radius 0.01095
            }
          }
        ]
        name "fl_coxa"
        boundingObject USE ShapeFCoxa
        physics Physics {
        }
      }
    }
    DEF legFR Hinge2Joint {
      jointParameters HingeJointParameters {
        position 0.09695071810268001
        axis 0 0 1
        anchor 0.23902 0.07 -0.02
      }
      jointParameters2 JointParameters {
        position 3.469324546846413e-05
        axis 1 0 0
      }
      device [
        DEF motor1 RotationalMotor {
          name "MotorLegRF1"
          maxTorque 50
        }
        PositionSensor {
          name "PSensorLegRF1"
        }
      ]
      device2 [
        PositionSensor {
          name "PSensorLegRF2"
        }
        DEF motor2 RotationalMotor {
          name "MotorLegRF2"
          maxTorque 50
        }
      ]
      endPoint DEF solid Solid {
        translation 0.23999539737818126 0.07009486809072138 -0.019999999999968748
        rotation -0.3167141365656075 0.6707179417759775 -0.670693371280273 2.528134429139274
        children [
          DEF coxa HingeJoint {
            jointParameters HingeJointParameters {
              position -0.3465496384302496
              anchor 0 0 -0.02
            }
            device [
              DEF motor RotationalMotor {
                name "MotorLegRF3"
                maxTorque 50
              }
              PositionSensor {
                name "PSensorLegRF3"
              }
            ]
            endPoint DEF solid Solid {
              translation 2.220446049249834e-16 -0.04075855167383517 -0.13286602883702567
              rotation -1 0 0 0.34654963843025005
              children [
                DEF femur HingeJoint {
                  jointParameters HingeJointParameters {
                    position 1.586561790094742
                    anchor 0 0 -0.13
                  }
                  device [
                    DEF motor RotationalMotor {
                      name "MotorLegRF4"
                      maxTorque 50
                    }
                    PositionSensor {
                      name "PSensorLegRF4"
                    }
                  ]
                  endPoint DEF solid Solid {
                    translation -4.237176950638817e-06 0.10397426106969859 -0.12836012669044014
                    rotation 0.9999999999992708 8.335016336465201e-07 8.738460435041292e-07 1.5865622140407503
                    children [
                      DEF tibia HingeJoint {
                        jointParameters HingeJointParameters {
                          position 1.403245436230728e-06
                          anchor 0 0 -0.104
                        }
                        device [
                          DEF motor RotationalMotor {
                            name "MotorLegRF5"
                            maxTorque 50
                          }
                          PositionSensor {
                            name "PSensorLegRF5"
                          }
                        ]
                        endPoint Solid {
                          translation 0 1.4668722182526746e-07 -0.20999999999989669
                          rotation 1 0 0 1.40324322783873e-06
                          children [
                            Solid {
                              translation 0 0 -0.106
                              children [
                                DEF TSensorLegRF TouchSensor {
                                  translation -1.911925989639407e-06 -1.1698718571651057e-06 7.137281209601554e-06
                                  rotation 0.6886980383806248 0.7131688307359618 0.13071048464977986 5.6200547336182704e-08
                                  name "TSensorLegRF"
                                  boundingObject Sphere {
                                    radius 0.01
                                  }
                                  physics Physics {
                                    density 20
                                    centerOfMass [
                                      0 0 0
                                    ]
                                  }
                                }
                                DEF ShapeClaw Shape {
                                  appearance USE AppLeg
                                  geometry Sphere {
                                    radius 0.0095
                                  }
                                }
                              ]
                              name "fl_tarsus_claw"
                              boundingObject USE ShapeClaw
                              physics Physics {
                              }
                            }
                            DEF ShapeFTarsus Shape {
                              appearance DEF AppLeg PBRAppearance {
                                baseColor 0 0 0
                                roughness 0.5
                                metalness 0.4
                              }
                              geometry Capsule {
                                height 0.19333
                                radius 0.00584
                              }
                            }
                            TouchSensor {
                              translation 0 0 -0.106
                              name "TSensorLegFR"
                              boundingObject USE ShapeClaw
                            }
                          ]
                          name "fl_tarsus"
                          boundingObject USE ShapeFTarsus
                          physics Physics {
                          }
                        }
                      }
                      DEF ShapeFTibia Shape {
                        appearance USE AppLeg
                        geometry Capsule {
                          height 0.19346
                          radius 0.01095
                        }
                      }
                    ]
                    name "fl_tibia"
                    boundingObject USE ShapeFTibia
                    physics Physics {
                    }
                  }
                }
                DEF ShapeFFemur Shape {
                  appearance USE AppLeg
                  geometry Capsule {
                    height 0.2175
                    radius 0.0146
                  }
                }
              ]
              name "fl_femur"
              boundingObject USE ShapeFFemur
              physics Physics {
              }
            }
          }
          DEF ShapeFCoxa Shape {
            appearance USE AppLeg
            geometry Capsule {
              height 0.009
              radius 0.01095
            }
          }
        ]
        name "fr_coxa"
        boundingObject USE ShapeFCoxa
        physics Physics {
        }
      }
    }
    DEF legML Hinge2Joint {
      jointParameters HingeJointParameters {
        position -0.09695061728803125
        axis 0 0 1
        anchor 0.34 -0.02 -0.02
      }
      jointParameters2 JointParameters {
        position -0.0017711374219764671
        axis 1 0 0
      }
      device [
        DEF motor1 RotationalMotor {
          name "MotorLegLM1"
          maxTorque 50
        }
        PositionSensor {
          name "PSensorLegLM1"
        }
      ]
      device2 [
        DEF motor2 RotationalMotor {
          name "MotorLegLM2"
          maxTorque 50
        }
        PositionSensor {
          name "PSensorLegLM2"
        }
      ]
      endPoint DEF solid Solid {
        translation 0.34726930035693226 -0.050864508257834146 -0.029947249571745695
        rotation -0.9976588641429542 0.04839969743858282 -0.04831418099112997 1.574910318466177
        children [
          DEF ShapeMCoxa Shape {
            appearance USE AppLeg
            geometry Capsule {
              height 0.0146
              radius 0.0219
            }
          }
          DEF coxa HingeJoint {
            jointParameters HingeJointParameters {
              position -0.4116529594228947
              anchor 0 0 -0.027
            }
            device [
              DEF motor RotationalMotor {
                name "MotorLegLM3"
                maxTorque 50
              }
              PositionSensor {
                name "PSensorLegLM3"
              }
            ]
            endPoint DEF solid Solid {
              translation 0 -0.05735581746696767 -0.16332561307106264
              rotation -0.9999999999999999 0 0 0.41165295942289515
              children [
                DEF ShapeMFemur Shape {
                  appearance USE AppLeg
                  geometry Capsule {
                    height 0.26
                    radius 0.0146
                  }
                }
                DEF femur HingeJoint {
                  jointParameters HingeJointParameters {
                    position 1.4144231654604578
                    anchor 0 0 -0.147
                  }
                  device [
                    DEF motor RotationalMotor {
                      name "MotorLegLM4"
                      maxTorque 50
                    }
                    PositionSensor {
                      name "PSensorLegLM4"
                    }
                  ]
                  endPoint DEF solid Solid {
                    translation 0 0.12149922910065124 -0.16615560826358175
                    rotation 1 0 0 1.4144231654604575
                    children [
                      DEF ShapeMTibia Shape {
                        appearance USE AppLeg
                        geometry Capsule {
                          height 0.22074
                          radius 0.01095
                        }
                      }
                      DEF tibia HingeJoint {
                        jointParameters HingeJointParameters {
                          position -5.124092324152459e-05
                          anchor 0 0 -0.121
                        }
                        device [
                          DEF motor RotationalMotor {
                            name "MotorLegLM5"
                            maxTorque 50
                          }
                          PositionSensor {
                            name "PSensorLegLM5"
                          }
                        ]
                        endPoint Solid {
                          translation 0 -6.2213683819004475e-06 -0.25299999985339683
                          rotation -1 0 0 4.716911206630873e-05
                          children [
                            DEF ShapeMTarsus Shape {
                              appearance USE AppLeg
                              geometry Capsule {
                                height 0.254
                                radius 0.0059
                              }
                            }
                            Solid {
                              translation 0 0 -0.14
                              children [
                                DEF TSensorLegLM TouchSensor {
                                  translation 2.415809800204727e-06 -4.0008798774415766e-05 3.367445623270182e-05
                                  rotation -0.9964622556917908 -0.0786220306120199 -0.02969089564278778 1.417845605911583e-07
                                  name "TSensorLegLM"
                                  boundingObject Sphere {
                                    radius 0.01
                                  }
                                  physics Physics {
                                    density 20
                                    centerOfMass [
                                      0 0 0
                                    ]
                                  }
                                }
                                DEF ShapeClaw Shape {
                                  appearance USE AppLeg
                                  geometry Sphere {
                                    radius 0.0095
                                  }
                                }
                              ]
                              name "fl_tarsus_claw"
                              boundingObject USE ShapeClaw
                              physics Physics {
                              }
                            }
                            DEF t_sensor TouchSensor {
                              translation 0 0 -0.14
                              name "TSensorLegML"
                              boundingObject USE ShapeClaw
                            }
                          ]
                          boundingObject USE ShapeMTarsus
                          physics Physics {
                          }
                        }
                      }
                    ]
                    boundingObject USE ShapeMTibia
                    physics Physics {
                    }
                  }
                }
              ]
              boundingObject USE ShapeMFemur
              physics Physics {
              }
            }
          }
        ]
        boundingObject USE ShapeMCoxa
        physics Physics {
        }
      }
    }
    DEF legMR Hinge2Joint {
      jointParameters HingeJointParameters {
        position -0.09695154594912803
        axis 0 0 1
        anchor 0.34 0.02 -0.02
      }
      jointParameters2 JointParameters {
        position 0.015725050115357256
        axis 1 0 0
      }
      device [
        DEF motor1 RotationalMotor {
          name "MotorLegRM1"
          maxTorque 50
        }
        PositionSensor {
          name "PSensorLegRM1"
        }
      ]
      device2 [
        DEF motor2 RotationalMotor {
          name "MotorLegRM2"
          maxTorque 50
        }
        PositionSensor {
          name "PSensorLegRM2"
        }
      ]
      endPoint DEF solid Solid {
        translation 0.35287186595162345 0.04904365565656038 -0.029527913361646906
        rotation 0.03455220211896069 0.7122194643120558 -0.7011059691542919 3.2095909017272337
        children [
          DEF ShapeMCoxa Shape {
            appearance USE AppLeg
            geometry Capsule {
              height 0.0146
              radius 0.0219
            }
          }
          DEF coxa HingeJoint {
            jointParameters HingeJointParameters {
              position -0.3851473950550313
              anchor 0 0 -0.027
            }
            device [
              DEF motor RotationalMotor {
                name "MotorLegRM3"
                maxTorque 50
              }
              PositionSensor {
                name "PSensorLegRM3"
              }
            ]
            endPoint DEF solid Solid {
              translation 0 -0.05748279698386082 -0.16479905832149652
              rotation -1 0 0 0.38514739505503154
              children [
                DEF ShapeMFemur Shape {
                  appearance USE AppLeg
                  geometry Capsule {
                    height 0.26
                    radius 0.0146
                  }
                }
                DEF femur HingeJoint {
                  jointParameters HingeJointParameters {
                    position 1.3878913810515463
                    anchor 0 0 -0.147
                  }
                  device [
                    DEF motor RotationalMotor {
                      name "MotorLegRM4"
                      maxTorque 50
                    }
                    PositionSensor {
                      name "PSensorLegRM4"
                    }
                  ]
                  endPoint DEF solid Solid {
                    translation 0 0.12094829493941275 -0.16937207972560325
                    rotation 1 0 0 1.3878913810515463
                    children [
                      DEF ShapeMTibia Shape {
                        appearance USE AppLeg
                        geometry Capsule {
                          height 0.22074
                          radius 0.01095
                        }
                      }
                      DEF tibia HingeJoint {
                        jointParameters HingeJointParameters {
                          position -5.618218587562942e-05
                          anchor 0 0 -0.121
                        }
                        device [
                          DEF motor RotationalMotor {
                            name "MotorLegRM5"
                            maxTorque 50
                          }
                          PositionSensor {
                            name "PSensorLegRM5"
                          }
                        ]
                        endPoint Solid {
                          translation 0 -7.416048531685372e-06 -0.25299999979167753
                          rotation -1 0 0 5.618218381324919e-05
                          children [
                            DEF ShapeMTarsus Shape {
                              appearance USE AppLeg
                              geometry Capsule {
                                height 0.254
                                radius 0.0059
                              }
                            }
                            Solid {
                              translation 0 0 -0.14
                              children [
                                DEF TSensorLegRM TouchSensor {
                                  translation 2.0911670041812158e-05 -5.790338422009822e-05 5.3958056038930224e-05
                                  rotation -0.5779639858502956 -0.6536592071867517 -0.4885563139700748 2.7998280504427055e-07
                                  name "TSensorLegRM"
                                  boundingObject Sphere {
                                    radius 0.01
                                  }
                                  physics Physics {
                                    density 20
                                    centerOfMass [
                                      0 0 0
                                    ]
                                  }
                                }
                                DEF ShapeClaw Shape {
                                  appearance USE AppLeg
                                  geometry Sphere {
                                    radius 0.0095
                                  }
                                }
                              ]
                              name "fl_tarsus_claw"
                              boundingObject USE ShapeClaw
                              physics Physics {
                              }
                            }
                            TouchSensor {
                              name "TSensorLegMR"
                            }
                          ]
                          boundingObject USE ShapeMTarsus
                          physics Physics {
                          }
                        }
                      }
                    ]
                    boundingObject USE ShapeMTibia
                    physics Physics {
                    }
                  }
                }
              ]
              boundingObject USE ShapeMFemur
              physics Physics {
              }
            }
          }
        ]
        name "solid(1)"
        boundingObject USE ShapeMCoxa
        physics Physics {
        }
      }
    }
    DEF legHL Hinge2Joint {
      jointParameters HingeJointParameters {
        position 0.09694748398120155
        axis 0 0 1
        anchor 0.426276 -0.03 -0.0340389
      }
      jointParameters2 JointParameters {
        position -1.5566079521647794e-05
        axis 1 0 0
      }
      device [
        DEF motor1 RotationalMotor {
          name "MotorLegLH1"
          maxTorque 50
        }
        PositionSensor {
          name "PSensorLegLH1"
        }
      ]
      device2 [
        DEF motor2 RotationalMotor {
          name "MotorLegLH2"
          maxTorque 50
        }
        PositionSensor {
          name "PSensorLegLH2"
        }
      ]
      endPoint DEF solid Solid {
        translation 0.43385433978677623 -0.06945169420977959 -0.0299999051665534
        rotation -0.8316127769254755 -0.39269490359375164 0.3926969594302882 1.7541669510533942
        children [
          DEF ShapeHCoxa Shape {
            appearance USE AppLeg
            geometry Capsule {
              height 0.04926
              radius 0.0219
            }
          }
          DEF coxa HingeJoint {
            jointParameters HingeJointParameters {
              position -0.7780850376260948
              anchor 0 0 -0.046
            }
            device [
              DEF motor RotationalMotor {
                name "MotorLegLH3"
                maxTorque 50
              }
              PositionSensor {
                name "PSensorLegLH3"
              }
            ]
            endPoint DEF solid Solid {
              translation 0 -0.12915268344717012 -0.17705565366813658
              rotation -1 0 0 0.778085037626095
              children [
                DEF ShapeHFemur Shape {
                  appearance USE AppLeg
                  geometry Capsule {
                    height 0.336
                    radius 0.0146
                  }
                }
                DEF femur HingeJoint {
                  jointParameters HingeJointParameters {
                    position 1.8069856652837593
                    anchor 0 0 -0.184
                  }
                  device [
                    DEF motor RotationalMotor {
                      name "MotorLegLH4"
                      maxTorque 50
                    }
                    PositionSensor {
                      name "PSensorLegLH4"
                    }
                  ]
                  endPoint DEF solid Solid {
                    translation 0 0.1575023493609068 -0.1460920859741074
                    rotation 1 0 0 1.8069856652837593
                    children [
                      DEF ShapeHTibia Shape {
                        appearance USE AppLeg
                        geometry Capsule {
                          height 0.3
                          radius 0.01095
                        }
                      }
                      DEF tibia HingeJoint {
                        jointParameters HingeJointParameters {
                          position 6.680938686475912e-06
                          anchor 0 0 -0.161
                        }
                        device [
                          DEF motor RotationalMotor {
                            name "MotorLegLH5"
                            maxTorque 50
                          }
                          PositionSensor {
                            name "PSensorLegLH5"
                          }
                        ]
                        endPoint Solid {
                          translation 0 1.8407743452895631e-06 -0.33599999999034114
                          rotation 1 0 0 6.680906997081429e-06
                          children [
                            DEF ShapeHTarsus Shape {
                              appearance USE AppLeg
                              geometry Capsule {
                                height 0.339
                                radius 0.0059
                              }
                            }
                            Solid {
                              translation 0 0 -0.18
                              children [
                                DEF TSensorLegLH TouchSensor {
                                  translation -2.068585902337272e-05 -2.55734090139903e-05 4.161916783873565e-06
                                  rotation -0.5060833785035522 0.7336327033204405 0.4535004637496776 1.9494929918322925e-07
                                  name "TSensorLegLH"
                                  boundingObject Sphere {
                                    radius 0.01
                                  }
                                  physics Physics {
                                    density 20
                                    centerOfMass [
                                      0 0 0
                                    ]
                                  }
                                }
                                DEF ShapeClaw Shape {
                                  appearance USE AppLeg
                                  geometry Sphere {
                                    radius 0.0095
                                  }
                                }
                              ]
                              name "fl_tarsus_claw"
                              boundingObject USE ShapeClaw
                              physics Physics {
                              }
                            }
                            DEF t_sensor TouchSensor {
                              translation 0 0 -0.18
                              name "TSensorLegHL"
                              boundingObject USE ShapeClaw
                            }
                          ]
                          boundingObject USE ShapeHTarsus
                          physics Physics {
                          }
                        }
                      }
                    ]
                    boundingObject USE ShapeHTibia
                    physics Physics {
                    }
                  }
                }
              ]
              boundingObject USE ShapeHFemur
              physics Physics {
              }
            }
          }
        ]
        name "solid(2)"
        boundingObject USE ShapeHCoxa
        physics Physics {
        }
      }
    }
    DEF legHR Hinge2Joint {
      jointParameters HingeJointParameters {
        position 0.09695985558720084
        axis 0 0 1
        anchor 0.426276 0.03 -0.0340389
      }
      jointParameters2 JointParameters {
        position 1.2255236006555523e-05
        axis 1 0 0
      }
      device [
        DEF motor1 RotationalMotor {
          name "MotorLegRH1"
          maxTorque 50
        }
        PositionSensor {
          name "PSensorLegRH1"
        }
      ]
      device2 [
        DEF motor2 RotationalMotor {
          name "MotorLegRH2"
          maxTorque 50
        }
        PositionSensor {
          name "PSensorLegRH2"
        }
      ]
      endPoint DEF solid Solid {
        translation 0.42611018084043645 0.07017271480425841 -0.030000784291877376
        rotation -0.24571728426213313 -0.6854327381442711 0.68542321064791 2.6597013339181164
        children [
          DEF ShapeHCoxa Shape {
            appearance USE AppLeg
            geometry Capsule {
              height 0.04926
              radius 0.0219
            }
          }
          DEF coxa HingeJoint {
            jointParameters HingeJointParameters {
              position -0.8045240523287751
              anchor 0 0 -0.046
            }
            device [
              DEF motor RotationalMotor {
                name "MotorLegRH3"
                maxTorque 50
              }
              PositionSensor {
                name "PSensorLegRH3"
              }
            ]
            endPoint DEF solid Solid {
              translation -6.333731270568978e-07 -0.13258101988755136 -0.17359388336726578
              rotation -0.9999999999997987 5.992596607899033e-07 2.088615735202125e-07 0.8045240523313999
              children [
                DEF ShapeHFemur Shape {
                  appearance USE AppLeg
                  geometry Capsule {
                    height 0.336
                    radius 0.0146
                  }
                }
                DEF femur HingeJoint {
                  jointParameters HingeJointParameters {
                    position 1.83352036793711
                    anchor 0 0 -0.184
                  }
                  device [
                    DEF motor RotationalMotor {
                      name "MotorLegRH4"
                      maxTorque 50
                    }
                    PositionSensor {
                      name "PSensorLegRH4"
                    }
                  ]
                  endPoint DEF solid Solid {
                    translation 0 0.15644114747139531 -0.1419266428979832
                    rotation 1 0 0 1.83352036793711
                    children [
                      DEF ShapeHTibia Shape {
                        appearance USE AppLeg
                        geometry Capsule {
                          height 0.3
                          radius 0.01095
                        }
                      }
                      DEF tibia HingeJoint {
                        jointParameters HingeJointParameters {
                          position 1.8999092112619137e-07
                          anchor 0 0 -0.161
                        }
                        device [
                          DEF motor RotationalMotor {
                            name "MotorLegRH5"
                            maxTorque 50
                          }
                          PositionSensor {
                            name "PSensorLegRH5"
                          }
                        ]
                        endPoint Solid {
                          translation 0 1.4904773094515156e-08 -0.33600000000744223
                          rotation 1 0 0 1.9082797281243954e-07
                          children [
                            DEF ShapeHTarsus Shape {
                              appearance USE AppLeg
                              geometry Capsule {
                                height 0.339
                                radius 0.0059
                              }
                            }
                            Solid {
                              translation 0 0 -0.18
                              children [
                                DEF TSensorLegRH TouchSensor {
                                  translation -8.116438676708526e-08 -3.755732073118523e-06 -3.4753421190858447e-06
                                  rotation -0.43271429426197816 -0.7644919525437146 -0.477818369296595 2.4829611482984447e-11
                                  name "TSensorLegRH"
                                  boundingObject Sphere {
                                    radius 0.01
                                  }
                                  physics Physics {
                                    density 20
                                    centerOfMass [
                                      0 0 0
                                    ]
                                  }
                                }
                                DEF ShapeClaw Shape {
                                  appearance USE AppLeg
                                  geometry Sphere {
                                    radius 0.0095
                                  }
                                }
                              ]
                              name "fl_tarsus_claw"
                              boundingObject USE ShapeClaw
                              physics Physics {
                              }
                            }
                            DEF t_sensor TouchSensor {
                              translation 0 0 -0.18
                              name "TSensorLegHR"
                              boundingObject USE ShapeClaw
                            }
                          ]
                          boundingObject USE ShapeHTarsus
                          physics Physics {
                          }
                        }
                      }
                    ]
                    boundingObject USE ShapeHTibia
                    physics Physics {
                    }
                  }
                }
              ]
              boundingObject USE ShapeHFemur
              physics Physics {
              }
            }
          }
        ]
        name "solid(3)"
        boundingObject USE ShapeHCoxa
        physics Physics {
        }
      }
    }
    DEF thorax Transform {
      translation 0.19 0 0
      rotation 0 1 0 -1.5707953071795862
      children [
        DEF ShapeThorax Shape {
          appearance USE AppLeg
          geometry Capsule {
            height 0.05839
            radius 0.06642
          }
        }
      ]
    }
    DEF petiole Transform {
      translation 0.368 0 0
      rotation 0 1 0 1.5708
      children [
        DEF ShapePetiole Shape {
          appearance USE AppLeg
          geometry Capsule {
            height 0.084
            radius 0.04
          }
        }
      ]
    }
    Pen {
      translation 0 0 -0.19
      inkColor 0.3294117748737335 0.5098039507865906 0.2078431397676468
      inkDensity 0.2
    }
    Transform {
      translation 0.09 0 -0.00999954
      rotation 0 1 0 -1.5707953071795862
      children [
        Shape {
          appearance USE AppLeg
          geometry Cone {
            bottomRadius 0.03
            height 0.03
          }
        }
      ]
    }
    Transform {
      translation 0.45 0 -0.0099999
      rotation 0 1 0 -1.5707953071795862
      children [
        Shape {
          appearance USE AppLeg
          geometry Cone {
            bottomRadius 0.02
            height 0.07
          }
        }
      ]
    }
  ]
  name "desert_ant"
  boundingObject Transform {
    translation 0.274 0 0
    rotation 0 1 0 1.5708
    children [
      Shape {
        geometry Cylinder {
          height 0.36
          radius 0.065
        }
      }
    ]
  }
  physics Physics {
    density 600
  }
  controller "I2Bot"
  supervisor TRUE
  window "AIBot"
}
Solid {
  rotation 0 1 0 0
  children [
    DEF floor Shape {
      appearance Appearance {
        texture ImageTexture {
          url [
            "textures/sand.jpg"
          ]
        }
      }
      geometry Plane {
        size 12 12
      }
    }
  ]
  boundingObject USE floor
}
DEF VisualScene Transform {
  scale 0.3 0.3 0.3
  children [
    Transform {
      translation -7.66 -13.68 4
      children [
        Shape {
          appearance PBRAppearance {
            baseColor 0 0.666667 0.666667
            roughness 1
            metalness 0
          }
          geometry Cylinder {
            height 8
            radius 2
          }
        }
      ]
    }
    Transform {
      translation -15.09 -0.5 4
      children [
        Shape {
          appearance PBRAppearance {
            baseColor 1 0 0
            roughness 0.1
            metalness 0
          }
          geometry Sphere {
            radius 4
            subdivision 4
          }
        }
      ]
    }
    Transform {
      translation 9.03 -11.01 6
      rotation 0 1 0 0
      children [
        Shape {
          appearance PBRAppearance {
            baseColor 1 0.666667 0.498039
            roughness 1
            metalness 0
          }
          geometry Box {
            size 6 4 12
          }
        }
      ]
    }
    Transform {
      translation -5.75324 14.0345 4
      rotation 0 0 1 -1.047195307179586
      children [
        Shape {
          appearance PBRAppearance {
            baseColor 0.498039 0.121569 0.00392157
            roughness 1
            metalness 0
          }
          geometry Box {
            size 3 12 8
          }
        }
      ]
    }
    Transform {
      translation 12.62 9.09 7
      rotation 0 1 0 0
      children [
        Shape {
          appearance PBRAppearance {
            baseColor 0.333333 0.333333 1
            roughness 1
            metalness 0
          }
          geometry Cone {
            bottomRadius 4
            height 14
            subdivision 20
          }
        }
      ]
    }
  ]
}
